Workbook

Sheet Parameter Categories
A1: Category | B1: Parameter | C1: Description | D1: Data Source | E1: Data Type | F1: Material | G1: Element
A2: 1. Identification and General Information | B2: Product Name | C2: Name of the material | D2: Manufacturer documentation | E2: Text | F2: x | G2: x
B3: Product ID | C3: Unique identifier of the material | D3: Certification or compliance report | E3: String | F3: x | G3: x
B4: Product Image | C4: Image of material in PNG | D4: Manufacturer documentation | E4: Image | F4: x
B5: Object number | C5: Unique BIM-generated object reference | D5: BIM parameter | E5: String | F5: x | G5: x
B6: Material Type | C6: Category or type of material | D6: BIM parameter | E6: Text | F6: x | G6: x
B7: Manufacturer | C7: Producer of the material | D7: Manufacturer documentation | E7: Text | F7: x | G7: x
B8: Link Manufacturer | C8: URL to manufacturer page | D8: Manufacturer documentation | E8: String | F8: x | G8: x
B9: Distributor | C9: Name and contact of distributor | D9: Manufacturer documentation | E9: Text | F9: x
B10: Link Distributor | C10: URL to distributor page | D10: Distributor documentation | E10: String | F10: x
B11: Supplier | C11: Name and contact of supplier or sub-supplier | D11: Manufacturer documentation | E11: Text | F11: x
B12: Link Supplier | C12: URL to supplier page | D12: Supplier documentation | E12: String | F12: x
B13: Transportation Route | C13: Typical transport routes and modes | D13: Manufacturer documentation | E13: Text | F13: x
B14: Traceability ID | C14: Unique digital ID for traceability (QR or blockchain) | D14: Manufacturer documentation | E14: String | F14: x | G14: x
B15: Origin | C15: Geographic source product | D15: Manufacturer documentation | E15: Text | F15: x | G15: x
B16: Version number | C16: Passport version control | D16: Assigned | E16: String | F16: x | G16: x
A17: 2. Physical and Technical Properties | B17: Material | C17: Description of the material | D17: Manufacturer documentation | E17: Text | F17: x
B18: Component | C18: Description of the component | D18: Manufacturer documentation | E18: Text | G18: x
B19: Composition | C19: Material composition and proportions | D19: Manufacturer documentation | E19: Text | F19: x | G19: x
B20: Dimensions | C20: Dimention type (cm) | D20: Manufacturer documentation | E20: Text | F20: x | G20: x
B21: Height | C21: Height of the material (mm) | D21: BIM parameter | E21: Numeric | F21: x | G21: x
B22: Length | C22: Length of the material (mm) | D22: BIM parameter | E22: Numeric | F22: x | G22: x
B23: Width | C23: Width of the material (mm) | D23: BIM parameter | E23: Numeric | F23: x | G23: x
B24: Volume | C24: Volume of the material(m³) | D24: Manufacturer documentation | E24: Numeric | F24: x | G24: x
B25: Dry density | C25: Mass per unit volume completely oven-dried (kg/m³) | D25: Manufacturer documentation | E25: Numeric | F25: x | G25: x
B26: Equilibrium density | C26: Mass per unit volume on normal ambient conditions (kg/m³) | D26: Manufacturer documentation | E26: Numeric | F26: x | G26: x
B27: Weight | C27: Mass per unit (kg) | D27: Manufacturer documentation | E27: Numeric | F27: x | G27: x
B28: Compressive strength | C28: Compressive resistance (Mpa) | D28: Laboratory test | E28: Numeric | F28: x | G28: x
B29: Shear strength | C29: Flextural resistance (Mpa) | D29: Laboratory test | E29: Numeric | F29: x | G29: x
B30: Thermal conductivity | C30: λ-value (W/mK) | D30: Laboratory test | E30: Numeric | G30: x
B31: Heat transfer coefficient | C31: u-value (W/m²K) | D31: Laboratory test | E31: Numeric | G31: x
B32: Sprecific heat capacity | C32: Heat required to raise temperature (J/kg·K) | D32: Laboratory test | E32: Numeric | G32: x
B33: Phase shift | C33: Delay in heat transfer through material (hours) | D33: Laboratory test | E33: Numeric | G33: x
B34: Moisture Buffer Value | C34: Moisture absorption/desorption capacity of the material | D34: Laboratory test | E34: Numeric | G34: x
B35: Water vapour diffusion resistance when wet | C35: Ability of material to allow vapor to pass through | D35: Laboratory test | E35: Numeric | F35: x | G35: x
B36: Water vapour diffusion resistance when dry | C36: Ability of material to allow vapor to pass through | D36: Laboratory test | E36: Numeric | F36: x | G36: x
B37: Water vapour absorption resistance | C37: Resistance to vapor absorption at surface | D37: Laboratory test | E37: Numeric | F37: x | G37: x
B38: Standard compliance | C38: Of relevant building or environmental standards | D38: Certification or compliance report | E38: Boolean | F38: x | G38: x
A39: 3. Circularity and End-of-Life Information | B39: Connection Type | C39: Type of material connection (Dry interlock / bolted / screwed; Mortar / adhesive / binder-based; Cast-in-place) | D39: Manufacturer documentation | E39: Text | G39: x
B40: Connection Score | C40: Ease of separation or reversibility score | D40: Assigned | E40: Numeric | G40: x
...

Sheet Shared parameters
A1: Parameter | B1: Name | C1: Group | D1: Data Type
A2: =INDEX(Categories[Parameter],ROW(B1)) -> Product Name | B2: DPP_AUT_Name | C2: AUT_Authoring | D2: Text
A3: =INDEX(Categories[Parameter],ROW(B2)) -> Product ID | B3: DPP_AUT_ID | C3: AUT_Authoring | D3: Text
A4: =INDEX(Categories[Parameter],ROW(B3)) -> Product Image | B4: DPP_AUT_Image | C4: AUT_Authoring | D4: Image
A5: =INDEX(Categories[Parameter],ROW(B4)) -> Object number | B5: DPP_AUT_GUID | C5: AUT_Authoring | D5: Text
A6: =INDEX(Categories[Parameter],ROW(B5)) -> Material Type | B6: DPP_AUT_MaterialType | C6: AUT_Authoring | D6: Text
A7: =INDEX(Categories[Parameter],ROW(B6)) -> Manufacturer | B7: DPP_AUT_Manufacturer | C7: AUT_Authoring | D7: Text
A8: =INDEX(Categories[Parameter],ROW(B7)) -> Link Manufacturer | B8: DPP_AUT_Manufacturer_URL | C8: AUT_Authoring | D8: URL
A9: =INDEX(Categories[Parameter],ROW(B8)) -> Distributor | B9: DPP_AUT_Distribuitor | C9: AUT_Authoring | D9: Text
A10: =INDEX(Categories[Parameter],ROW(B9)) -> Link Distributor | B10: DPP_AUT_Distribuitor_URL | C10: AUT_Authoring | D10: URL
A11: =INDEX(Categories[Parameter],ROW(B10)) -> Supplier | B11: DPP_AUR_Supplier | C11: AUT_Authoring | D11: Text
A12: =INDEX(Categories[Parameter],ROW(B11)) -> Link Supplier | B12: DPP_AUR_Supplier_URL | C12: AUT_Authoring | D12: URL
A13: =INDEX(Categories[Parameter],ROW(B12)) -> Transportation Route | B13: DPP_AUT_TransRoute | C13: AUT_Authoring | D13: Multiline Text
... A117: =INDEX(Categories[Parameter],ROW(B116)) -> Lifecycle cost estimate | B117: DPP_COD_LCC_EUR | C117: COD_CostData | D117: Cost per area

Sheet Built In Parameter groups
A1: Group parameter Under Names | B1: Revit API name | C1: BP Group | D1: Type | E1: Definition
A2: Analysis Results | B2: Analysis Results | C2: PG_ANALYSIS_RESULTS | D2: Analysis & Analytical Groups | E2: For displaying calculated values (e.g., structural or energy analysis outputs)
A3: Analytical Alignment | B3: AnalyticalAlignment | C3: PG_ALIGNMENT | D3: Analysis & Analytical Groups | E3: For parameters defining analytical model alignment or adjustments
A4: Analytical Model | B4: AnalyticalModel | C4: PG_ANALYTICAL_MODEL | D4: Analysis & Analytical Groups | E4: For parameters related to analytical representation of physical elements
A5: Constraints | B5: Constraints | C5: PG_CONSTRAINTS | D5: Construction & Constraints | E5: For controlling element relationships (e.g., levels, offsets, locked dimensions)
A6: Construction | B6: Construction | C6: PG_CONSTRUCTION | D6: Construction & Constraints | E6: For parameters related to construction sequencing, methods, or materials
A7: Data | B7: Data | C7: PG_DATA | D7: Data & Geometry | E7: General-purpose data parameters (e.g., IDs, classification codes)
A8: Dimensions | B8: Geometry | C8: PG_DIMENSIONS | D8: Data & Geometry | E8: For numeric or size parameters (height, width, depth, etc.)
A9: Division Geometry | B9: DivisionGeometry | C9: PG_GEOMETRY | D9: Data & Geometry | E9: For subdivision or geometry-based controls, typically used in civil/landscape or curtain systems
A10: Electrical | B10: Electrical | C10: PG_ELECTRICAL | D10: Electrical | E10: General electrical parameters (e.g., voltage, panel, circuit)
A11: Electrical - Circuiting | B11: ElectricalCircuiting | C11: PG_CIRCUITING | D11: Electrical | E11: Circuit connection parameters (load classification, circuit number)
A12: Electrical - Lighting | B12: ElectricalLighting | C12: PG_LIGHTING | D12: Electrical | E12: For light fixtures, wattage, illumination levels
... A52: Visualization | B52: Visualization | C52: PG_VISUALIZATION | D52: Documentation & Text | E52: For rendering or appearance settings

Sheet Data Entry
A1: Parameter | B1: Data | C1: Unit | D1: Range | E1: Source | F1: Formulas
A2: =+INDEX(Categories[Parameter],ROW(B1)) -> Product Name | B2: Hempstone | C2: — | D2: — | E2: Technical data sheet 06/2025
A3: =+INDEX(Categories[Parameter],ROW(B2)) -> Product ID | B3: Z-17.25-1299 | C3: ID | D3: — | E3: German general type approval
A4: =+INDEX(Categories[Parameter],ROW(B3)) -> Product Image | B4: ..\..\werner schönthaler\hanfsteine Sch├Ânthaler Kopie.png | C4: — | D4: — | E4: Sent by Manufacturer
A5: =+INDEX(Categories[Parameter],ROW(B4)) -> Object number | C5: GUID | D5: — | E5: BIM parameter
A6: =+INDEX(Categories[Parameter],ROW(B5)) -> Material Type | B6: Type II | C6: — | D6: Type I (Ingredients); Type II (Modular); Type III (Sub-Components) | E6: Waterman materials passport framework 2023
A7: =+INDEX(Categories[Parameter],ROW(B6)) -> Manufacturer | B7: Schönthaler Bausteinwerk GmbH | C7: — | D7: — | E7: German general type approval
A8: =+INDEX(Categories[Parameter],ROW(B7)) -> Link Manufacturer | B8: https://www.hanfstein.eu/ | C8: — | D8: — | E8: Sent by Manufacturer
A9: =+INDEX(Categories[Parameter],ROW(B8)) -> Distributor | B9: NA | C9: — | D9: NA
A10: =+INDEX(Categories[Parameter],ROW(B9)) -> Link Distributor | B10: NA | C10: — | D10: NA
A11: =+INDEX(Categories[Parameter],ROW(B10)) -> Supplier | B11: NA | C11: — | D11: NA
A12: =+INDEX(Categories[Parameter],ROW(B11)) -> Link Supplier | B12: NA | C12: — | D12: NA
A13: =+INDEX(Categories[Parameter],ROW(B12)) -> Transportation Route
A14: =+INDEX(Categories[Parameter],ROW(B13)) -> Traceability ID | B14: a1b2c3d4-e5f6-7890-1234-567890abcdef | C14: QR | D14: QR-RFID-NFC-Serial number | E14: Example of a QR code string
A15: =+INDEX(Categories[Parameter],ROW(B14)) -> Origin | B15: 39020 Oris (BZ) | C15: — | D15: — | E15: German general type approval
A16: =+INDEX(Categories[Parameter],ROW(B15)) -> Version number | B16: HKZ 335 | C16: No. | D16: HKZ 335 - HKZ 360 | E16: Assigned
A17: =+INDEX(Categories[Parameter],ROW(B16)) -> Material | B17: Infill masonry made of hemp stones | C17: — | D17: — | E17: BIM parameter
A18: =+INDEX(Categories[Parameter],ROW(B17)) -> Component | B18: 8 hempstone bricks of 8x50x20 with a 1/3 displacement with hemp-lime mortar | C18: — | D18: —
A19: =+INDEX(Categories[Parameter],ROW(B18)) -> Composition | B19: Hemp-lime composite | C19: — | D19: Hemp-clay; Hemp-cement; Hemp-biopolymer; Hemp-MgO | E19: Technical data sheet 06/2025 (Range by Steyn et al., 2025; Barbhuiya & Bhusan, 2022)
A20: =+INDEX(Categories[Parameter],ROW(B19)) -> Dimensions | B20: 8x50x20 | C20: cm | D20: 6x22x11; 8x50x20; 12x55x20; 15x50x20; 20x55x20; 24x55x20; 38x55x20; 44x55x20 | E20: Technical data sheet 2017
A21: =+INDEX(Categories[Parameter],ROW(B20)) -> Height | B21: 200 | C21: mm | D21: 200 - 300 | E21: BIM parameter (Range by standard masonry formats)
A22: =+INDEX(Categories[Parameter],ROW(B21)) -> Length | B22: 80 | C22: mm | D22: 100 - 250 | E22: BIM parameter (Range by standard masonry formats)
A23: =+INDEX(Categories[Parameter],ROW(B22)) -> Width | B23: 500 | C23: mm | D23: 300 - 600 | E23: BIM parameter (Range by standard masonry formats)
A24: =+INDEX(Categories[Parameter],ROW(B23)) -> Volume | B24: 0.008 | C24: — | D24: 0.006 - 0.036 | E24: Calculated | F24: Height*Lenght*Width
A25: =+INDEX(Categories[Parameter],ROW(B24)) -> Dry density | B25: 335 | C25: kg/m³ | D25: 310-360 | E25: EPD 2025
A26: =+INDEX(Categories[Parameter],ROW(B25)) -> Equilibrium density | B26: 405 | C26: kg/m³ | D26: 390-450 | E26: EPD 2025
A27: =+INDEX(Categories[Parameter],ROW(B26)) -> Weight | B27: 2.68 | C27: Kg | D27: 6.00 - 15.00 | E27: Calculated | F27: Volume*Dry density
A28: =+INDEX(Categories[Parameter],ROW(B27)) -> Compressive strength | B28: 0.5 | C28: Mpa | D28: 0.06-0.8 | E28: Technical data sheet 06/2025 (Range by Steyn et al., 2025; Asghari & Memari, 2024)
A29: =+INDEX(Categories[Parameter],ROW(B28)) -> Shear strength | B29: 0.12 | C29: Mpa | D29: 0.08-0.15 | E29: Hempblock brochure (Range by Steyn et al., 2025; Brzyski et al., 2020)
A30: =+INDEX(Categories[Parameter],ROW(B29)) -> Thermal conductivity | B30: 0.07 | C30: W/(mK) | D30: 0.05-0.22 | E30: Technical data sheet 06/2025 (Range by Collet & Pretot in Steyn et al., 2025)
A31: =+INDEX(Categories[Parameter],ROW(B30)) -> Heat transfer coefficient | B31: 0.76 | C31: W/(m²K) | D31: 0.15-0.76 | E31: Technical data sheet 06/2025
A32: =+INDEX(Categories[Parameter],ROW(B31)) -> Sprecific heat capacity | B32: 1870 | C32: (J/kg.K) | E32: Technical data sheet 06/2025
A33: =+INDEX(Categories[Parameter],ROW(B32)) -> Phase shift | B33: 0.13125 | C33: Hours | D33: 3:09-24:30 | E33: Technical data sheet 06/2025
A34: =+INDEX(Categories[Parameter],ROW(B33)) -> Moisture Buffer Value | B34: 2.35 | C34: g/m²%HR | D34: 0-2.5 | E34: Technical data sheet 2017
A35: =+INDEX(Categories[Parameter],ROW(B34)) -> Water vapour diffusion resistance when wet | B35: 3.8 | C35: μ | D35: 4.9 - 5.7 | E35: Technical data sheet 06/2025 (Range by Brzyski et al., 2020)
A36: =+INDEX(Categories[Parameter],ROW(B35)) -> Water vapour diffusion resistance when dry | B36: 4.3 | C36: μ | D36: 12.2 - 12.4 | E36: Technical data sheet 06/2025 (Range by Brzyski et al., 2020)
A37: =+INDEX(Categories[Parameter],ROW(B36)) -> Water vapour absorption resistance | B37: 19 | C37: d[g/m²vh] | D37: — | E37: Technical data sheet 06/2025
A38: =+INDEX(Categories[Parameter],ROW(B37)) -> Standard compliance | B38: Yes | C38: — | D38: Yes/No | E38: German general type approval
A39: =+INDEX(Categories[Parameter],ROW(B38)) -> Connection Type | B39: Mortar | C39: — | D39: Dry interlock / bolted / screwed; Mortar / adhesive / binder-based; Cast-in-place | E39: https://www.hanfstein.eu/en/application/
A40: =+INDEX(Categories[Parameter],ROW(B39)) -> Connection Score | B40: 0.3 | C40: Score | D40: 0.0 (easy) - 1.0 (hard) | E40: Assigned
...

Sheet Manual workflow
A1: Shared Parameter Name | B1: Group name | C1: Instance | D1: Value
A2: =INDEX(SharedParams[Name],ROW(B1)) -> DPP_AUT_Name | B2: Identity Data | C2: =IFERROR( IF( VLOOKUP( INDEX('Shared parameters'!$A$2:$A$200, MATCH($A2,'Shared parameters'!$B$2:$B$200,0) ), 'Parameter Categories'!$B$2:$G$200, 6, FALSE )="x", "No", IF( VLOOKUP( INDEX('Shared parameters'!$A$2:$A$200, MATCH($A2,'Shared parameters'!$B$2:$B$200,0) ), 'Parameter Categories'!$B$2:$G$200, 5, FALSE )="x", "Yes", "" ) ), "") -> No | D2: =IFERROR( VLOOKUP( INDEX('Shared parameters'!$A$2:$A$200, MATCH($A2,'Shared parameters'!$B$2:$B$200,0) ), 'Data Entry'!$A$2:$B$200, 2, FALSE ), "") -> Hempstone
A3: =INDEX(SharedParams[Name],ROW(B2)) -> DPP_AUT_ID | B3: Identity Data | C3: =IFERROR( IF( VLOOKUP( INDEX('Shared parameters'!$A$2:$A$200, MATCH($A3,'Shared parameters'!$B$2:$B$200,0) ), 'Parameter Categories'!$B$2:$G$200, 6, FALSE )="x", "No", IF( VLOOKUP( INDEX('Shared parameters'!$A$2:$A$200, MATCH($A3,'Shared parameters'!$B$2:$B$200,0) ), 'Parameter Categories'!$B$2:$G$200, 5, FALSE )="x", "Yes", "" ) ), "") -> No | D3: =IFERROR( VLOOKUP( INDEX('Shared parameters'!$A$2:$A$200, MATCH($A3,'Shared parameters'!$B$2:$B$200,0) ), 'Data Entry'!$A$2:$B$200, 2, FALSE ), "") -> Z-17.25-1299
A4: =INDEX(SharedParams[Name],ROW(B3)) -> DPP_AUT_Image | B4: Identity Data | C4: =IFERROR( IF( VLOOKUP( INDEX('Shared parameters'!$A$2:$A$200, MATCH($A4,'Shared parameters'!$B$2:$B$200,0) ), 'Parameter Categories'!$B$2:$G$200, 6, FALSE )="x", "No", IF( VLOOKUP( INDEX('Shared parameters'!$A$2:$A$200, MATCH($A4,'Shared parameters'!$B$2:$B$200,0) ), 'Parameter Categories'!$B$2:$G$200, 5, FALSE )="x", "Yes", "" ) ), "") -> Yes | D4: =IFERROR( VLOOKUP( INDEX('Shared parameters'!$A$2:$A$200, MATCH($A4,'Shared parameters'!$B$2:$B$200,0) ), 'Data Entry'!$A$2:$B$200, 2, FALSE ), "") -> ..\..\werner schönthaler\hanfsteine Sch├Ânthaler Kopie.png
A5: =INDEX(SharedParams[Name],ROW(B4)) -> DPP_AUT_GUID | B5: Identity Data | C5: =IFERROR( IF( VLOOKUP( INDEX('Shared parameters'!$A$2:$A$200, MATCH($A5,'Shared parameters'!$B$2:$B$200,0) ), 'Parameter Categories'!$B$2:$G$200, 6, FALSE )="x", "No", IF( VLOOKUP( INDEX('Shared parameters'!$A$2:$A$200, MATCH($A5,'Shared parameters'!$B$2:$B$200,0) ), 'Parameter Categories'!$B$2:$G$200, 5, FALSE )="x", "Yes", "" ) ), "") -> No | D5: =IFERROR( VLOOKUP( INDEX('Shared parameters'!$A$2:$A$200, MATCH($A5,'Shared parameters'!$B$2:$B$200,0) ), 'Data Entry'!$A$2:$B$200, 2, FALSE ), "") -> 0
A6: =INDEX(SharedParams[Name],ROW(B5)) -> DPP_AUT_MaterialType | B6: Materials and Finishes | C6: =IFERROR( IF( VLOOKUP( INDEX('Shared parameters'!$A$2:$A$200, MATCH($A6,'Shared parameters'!$B$2:$B$200,0) ), 'Parameter Categories'!$B$2:$G$200, 6, FALSE )="x", "No", IF( VLOOKUP( INDEX('Shared parameters'!$A$2:$A$200, MATCH($A6,'Shared parameters'!$B$2:$B$200,0) ), 'Parameter Categories'!$B$2:$G$200, 5, FALSE )="x", "Yes", "" ) ), "") -> No | D6: =IFERROR( VLOOKUP( INDEX('Shared parameters'!$A$2:$A$200, MATCH($A6,'Shared parameters'!$B$2:$B$200,0) ), 'Data Entry'!$A$2:$B$200, 2, FALSE ), "") -> Type II
A7: =INDEX(SharedParams[Name],ROW(B6)) -> DPP_AUT_Manufacturer | B7: Identity Data | C7: =IFERROR( IF( VLOOKUP( INDEX('Shared parameters'!$A$2:$A$200, MATCH($A7,'Shared parameters'!$B$2:$B$200,0) ), 'Parameter Categories'!$B$2:$G$200, 6, FALSE )="x", "No", IF( VLOOKUP( INDEX('Shared parameters'!$A$2:$A$200, MATCH($A7,'Shared parameters'!$B$2:$B$200,0) ), 'Parameter Categories'!$B$2:$G$200, 5, FALSE )="x", "Yes", "" ) ), "") -> No | D7: =IFERROR( VLOOKUP( INDEX('Shared parameters'!$A$2:$A$200, MATCH($A7,'Shared parameters'!$B$2:$B$200,0) ), 'Data Entry'!$A$2:$B$200, 2, FALSE ), "") -> Schönthaler Bausteinwerk GmbH
A8: =INDEX(SharedParams[Name],ROW(B7)) -> DPP_AUT_Manufacturer_URL | B8: Identity Data | C8: =IFERROR( IF( VLOOKUP( INDEX('Shared parameters'!$A$2:$A$200, MATCH($A8,'Shared parameters'!$B$2:$B$200,0) ), 'Parameter Categories'!$B$2:$G$200, 6, FALSE )="x", "No", IF( VLOOKUP( INDEX('Shared parameters'!$A$2:$A$200, MATCH($A8,'Shared parameters'!$B$2:$B$200,0) ), 'Parameter Categories'!$B$2:$G$200, 5, FALSE )="x", "Yes", "" ) ), "") -> No | D8: =IFERROR( VLOOKUP( INDEX('Shared parameters'!$A$2:$A$200, MATCH($A8,'Shared parameters'!$B$2:$B$200,0) ), 'Data Entry'!$A$2:$B$200, 2, FALSE ), "") -> https://www.hanfstein.eu/
A9: =INDEX(SharedParams[Name],ROW(B8)) -> DPP_AUT_Distribuitor | B9: Identity Data | C9: =IFERROR( IF( VLOOKUP( INDEX('Shared parameters'!$A$2:$A$200, MATCH($A9,'Shared parameters'!$B$2:$B$200,0) ), 'Parameter Categories'!$B$2:$G$200, 6, FALSE )="x", "No", IF( VLOOKUP( INDEX('Shared parameters'!$A$2:$A$200, MATCH($A9,'Shared parameters'!$B$2:$B$200,0) ), 'Parameter Categories'!$B$2:$G$200, 5, FALSE )="x", "Yes", "" ) ), "") -> Yes | D9: =IFERROR( VLOOKUP( INDEX('Shared parameters'!$A$2:$A$200, MATCH($A9,'Shared parameters'!$B$2:$B$200,0) ), 'Data Entry'!$A$2:$B$200, 2, FALSE ), "") -> NA
A10: =INDEX(SharedParams[Name],ROW(B9)) -> DPP_AUT_Distribuitor_URL | B10: Identity Data | C10: =IFERROR( IF( VLOOKUP( INDEX('Shared parameters'!$A$2:$A$200, MATCH($A10,'Shared parameters'!$B$2:$B$200,0) ), 'Parameter Categories'!$B$2:$G$200, 6, FALSE )="x", "No", IF( VLOOKUP( INDEX('Shared parameters'!$A$2:$A$200, MATCH($A10,'Shared parameters'!$B$2:$B$200,0) ), 'Parameter Categories'!$B$2:$G$200, 5, FALSE )="x", "Yes", "" ) ), "") -> Yes | D10: =IFERROR( VLOOKUP( INDEX('Shared parameters'!$A$2:$A$200, MATCH($A10,'Shared parameters'!$B$2:$B$200,0) ), 'Data Entry'!$A$2:$B$200, 2, FALSE ), "") -> NA
A11: =INDEX(SharedParams[Name],ROW(B10)) -> DPP_AUR_Supplier | B11: Identity Data | C11: =IFERROR( IF( VLOOKUP( INDEX('Shared parameters'!$A$2:$A$200, MATCH($A11,'Shared parameters'!$B$2:$B$200,0) ), 'Parameter Categories'!$B$2:$G$200, 6, FALSE )="x", "No", IF( VLOOKUP( INDEX('Shared parameters'!$A$2:$A$200, MATCH($A11,'Shared parameters'!$B$2:$B$200,0) ), 'Parameter Categories'!$B$2:$G$200, 5, FALSE )="x", "Yes", "" ) ), "") -> Yes | D11: =IFERROR( VLOOKUP( INDEX('Shared parameters'!$A$2:$A$200, MATCH($A11,'Shared parameters'!$B$2:$B$200,0) ), 'Data Entry'!$A$2:$B$200, 2, FALSE ), "") -> NA
A12: =INDEX(SharedParams[Name],ROW(B11)) -> DPP_AUR_Supplier_URL | B12: Identity Data | C12: =IFERROR( IF( VLOOKUP( INDEX('Shared parameters'!$A$2:$A$200, MATCH($A12,'Shared parameters'!$B$2:$B$200,0) ), 'Parameter Categories'!$B$2:$G$200, 6, FALSE )="x", "No", IF( VLOOKUP( INDEX('Shared parameters'!$A$2:$A$200, MATCH($A12,'Shared parameters'!$B$2:$B$200,0) ), 'Parameter Categories'!$B$2:$G$200, 5, FALSE )="x", "Yes", "" ) ), "") -> Yes | D12: =IFERROR( VLOOKUP( INDEX('Shared parameters'!$A$2:$A$200, MATCH($A12,'Shared parameters'!$B$2:$B$200,0) ), 'Data Entry'!$A$2:$B$200, 2, FALSE ), "") -> NA
A13: =INDEX(SharedParams[Name],ROW(B12)) -> DPP_AUT_TransRoute | B13: Identity Data | C13: =IFERROR( IF( VLOOKUP( INDEX('Shared parameters'!$A$2:$A$200, MATCH($A13,'Shared parameters'!$B$2:$B$200,0) ), 'Parameter Categories'!$B$2:$G$200, 6, FALSE )="x", "No", IF( VLOOKUP( INDEX('Shared parameters'!$A$2:$A$200, MATCH($A13,'Shared parameters'!$B$2:$B$200,0) ), 'Parameter Categories'!$B$2:$G$200, 5, FALSE )="x", "Yes", "" ) ), "") -> Yes | D13: =IFERROR( VLOOKUP( INDEX('Shared parameters'!$A$2:$A$200, MATCH($A13,'Shared parameters'!$B$2:$B$200,0) ), 'Data Entry'!$A$2:$B$200, 2, FALSE ), "") -> 0
... A117: =INDEX(SharedParams[Name],ROW(B116)) -> DPP_COD_LCC_EUR | B117: Data | C117: =IFERROR( IF( VLOOKUP( INDEX('Shared parameters'!$A$2:$A$200, MATCH($A117,'Shared parameters'!$B$2:$B$200,0) ), 'Parameter Categories'!$B$2:$G$200, 6, FALSE )="x", "No", IF( VLOOKUP( INDEX('Shared parameters'!$A$2:$A$200, MATCH($A117,'Shared parameters'!$B$2:$B$200,0) ), 'Parameter Categories'!$B$2:$G$200, 5, FALSE )="x", "Yes", "" ) ), "") -> No | D117: =IFERROR( VLOOKUP( INDEX('Shared parameters'!$A$2:$A$200, MATCH($A117,'Shared parameters'!$B$2:$B$200,0) ), 'Data Entry'!$A$2:$B$200, 2, FALSE ), "") -> 47.376343

Sheet Dynamo workflow (add params)
A1: Shared Parameter Name | B1: Group name | C1: Instance
A2: =INDEX(SharedParams[Name],ROW(B1)) -> DPP_AUT_Name | B2: =IFERROR( VLOOKUP( INDEX('Manual workflow'!$B$2:$B$200, MATCH($A2,'Manual workflow'!$A$2:$A$200,0) ), 'Built In Parameter groups'!$A$2:$C$200, 2, FALSE ), "") -> IdentityData | C2: =IFERROR( IF( VLOOKUP( INDEX('Shared parameters'!$A$2:$A$200, MATCH($A2,'Shared parameters'!$B$2:$B$200,0) ), 'Parameter Categories'!$B$2:$G$200, 6, FALSE )="x", "No", IF( VLOOKUP( INDEX('Shared parameters'!$A$2:$A$200, MATCH($A2,'Shared parameters'!$B$2:$B$200,0) ), 'Parameter Categories'!$B$2:$G$200, 5, FALSE )="x", "Yes", "" ) ), "") -> No
A3: =INDEX(SharedParams[Name],ROW(B2)) -> DPP_AUT_ID | B3: =IFERROR( VLOOKUP( INDEX('Manual workflow'!$B$2:$B$200, MATCH($A3,'Manual workflow'!$A$2:$A$200,0) ), 'Built In Parameter groups'!$A$2:$C$200, 2, FALSE ), "") -> IdentityData | C3: =IFERROR( IF( VLOOKUP( INDEX('Shared parameters'!$A$2:$A$200, MATCH($A3,'Shared parameters'!$B$2:$B$200,0) ), 'Parameter Categories'!$B$2:$G$200, 6, FALSE )="x", "No", IF( VLOOKUP( INDEX('Shared parameters'!$A$2:$A$200, MATCH($A3,'Shared parameters'!$B$2:$B$200,0) ), 'Parameter Categories'!$B$2:$G$200, 5, FALSE )="x", "Yes", "" ) ), "") -> No
A4: =INDEX(SharedParams[Name],ROW(B3)) -> DPP_AUT_Image | B4: =IFERROR( VLOOKUP( INDEX('Manual workflow'!$B$2:$B$200, MATCH($A4,'Manual workflow'!$A$2:$A$200,0) ), 'Built In Parameter groups'!$A$2:$C$200, 2, FALSE ), "") -> IdentityData | C4: =IFERROR( IF( VLOOKUP( INDEX('Shared parameters'!$A$2:$A$200, MATCH($A4,'Shared parameters'!$B$2:$B$200,0) ), 'Parameter Categories'!$B$2:$G$200, 6, FALSE )="x", "No", IF( VLOOKUP( INDEX('Shared parameters'!$A$2:$A$200, MATCH($A4,'Shared parameters'!$B$2:$B$200,0) ), 'Parameter Categories'!$B$2:$G$200, 5, FALSE )="x", "Yes", "" ) ), "") -> Yes
A5: =INDEX(SharedParams[Name],ROW(B4)) -> DPP_AUT_GUID | B5: =IFERROR( VLOOKUP( INDEX('Manual workflow'!$B$2:$B$200, MATCH($A5,'Manual workflow'!$A$2:$A$200,0) ), 'Built In Parameter groups'!$A$2:$C$200, 2, FALSE ), "") -> IdentityData | C5: =IFERROR( IF( VLOOKUP( INDEX('Shared parameters'!$A$2:$A$200, MATCH($A5,'Shared parameters'!$B$2:$B$200,0) ), 'Parameter Categories'!$B$2:$G$200, 6, FALSE )="x", "No", IF( VLOOKUP( INDEX('Shared parameters'!$A$2:$A$200, MATCH($A5,'Shared parameters'!$B$2:$B$200,0) ), 'Parameter Categories'!$B$2:$G$200, 5, FALSE )="x", "Yes", "" ) ), "") -> No
A6: =INDEX(SharedParams[Name],ROW(B5)) -> DPP_AUT_MaterialType | B6: =IFERROR( VLOOKUP( INDEX('Manual workflow'!$B$2:$B$200, MATCH($A6,'Manual workflow'!$A$2:$A$200,0) ), 'Built In Parameter groups'!$A$2:$C$200, 2, FALSE ), "") -> Materials | C6: =IFERROR( IF( VLOOKUP( INDEX('Shared parameters'!$A$2:$A$200, MATCH($A6,'Shared parameters'!$B$2:$B$200,0) ), 'Parameter Categories'!$B$2:$G$200, 6, FALSE )="x", "No", IF( VLOOKUP( INDEX('Shared parameters'!$A$2:$A$200, MATCH($A6,'Shared parameters'!$B$2:$B$200,0) ), 'Parameter Categories'!$B$2:$G$200, 5, FALSE )="x", "Yes", "" ) ), "") -> No
A7: =INDEX(SharedParams[Name],ROW(B6)) -> DPP_AUT_Manufacturer | B7: =IFERROR( VLOOKUP( INDEX('Manual workflow'!$B$2:$B$200, MATCH($A7,'Manual workflow'!$A$2:$A$200,0) ), 'Built In Parameter groups'!$A$2:$C$200, 2, FALSE ), "") -> IdentityData | C7: =IFERROR( IF( VLOOKUP( INDEX('Shared parameters'!$A$2:$A$200, MATCH($A7,'Shared parameters'!$B$2:$B$200,0) ), 'Parameter Categories'!$B$2:$G$200, 6, FALSE )="x", "No", IF( VLOOKUP( INDEX('Shared parameters'!$A$2:$A$200, MATCH($A7,'Shared parameters'!$B$2:$B$200,0) ), 'Parameter Categories'!$B$2:$G$200, 5, FALSE )="x", "Yes", "" ) ), "") -> No
A8: =INDEX(SharedParams[Name],ROW(B7)) -> DPP_AUT_Manufacturer_URL | B8: =IFERROR( VLOOKUP( INDEX('Manual workflow'!$B$2:$B$200, MATCH($A8,'Manual workflow'!$A$2:$A$200,0) ), 'Built In Parameter groups'!$A$2:$C$200, 2, FALSE ), "") -> IdentityData | C8: =IFERROR( IF( VLOOKUP( INDEX('Shared parameters'!$A$2:$A$200, MATCH($A8,'Shared parameters'!$B$2:$B$200,0) ), 'Parameter Categories'!$B$2:$G$200, 6, FALSE )="x", "No", IF( VLOOKUP( INDEX('Shared parameters'!$A$2:$A$200, MATCH($A8,'Shared parameters'!$B$2:$B$200,0) ), 'Parameter Categories'!$B$2:$G$200, 5, FALSE )="x", "Yes", "" ) ), "") -> No
A9: =INDEX(SharedParams[Name],ROW(B8)) -> DPP_AUT_Distribuitor | B9: =IFERROR( VLOOKUP( INDEX('Manual workflow'!$B$2:$B$200, MATCH($A9,'Manual workflow'!$A$2:$A$200,0) ), 'Built In Parameter groups'!$A$2:$C$200, 2, FALSE ), "") -> IdentityData | C9: =IFERROR( IF( VLOOKUP( INDEX('Shared parameters'!$A$2:$A$200, MATCH($A9,'Shared parameters'!$B$2:$B$200,0) ), 'Parameter Categories'!$B$2:$G$200, 6, FALSE )="x", "No", IF( VLOOKUP( INDEX('Shared parameters'!$A$2:$A$200, MATCH($A9,'Shared parameters'!$B$2:$B$200,0) ), 'Parameter Categories'!$B$2:$G$200, 5, FALSE )="x", "Yes", "" ) ), "") -> Yes
A10: =INDEX(SharedParams[Name],ROW(B9)) -> DPP_AUT_Distribuitor_URL | B10: =IFERROR( VLOOKUP( INDEX('Manual workflow'!$B$2:$B$200, MATCH($A10,'Manual workflow'!$A$2:$A$200,0) ), 'Built In Parameter groups'!$A$2:$C$200, 2, FALSE ), "") -> IdentityData | C10: =IFERROR( IF( VLOOKUP( INDEX('Shared parameters'!$A$2:$A$200, MATCH($A10,'Shared parameters'!$B$2:$B$200,0) ), 'Parameter Categories'!$B$2:$G$200, 6, FALSE )="x", "No", IF( VLOOKUP( INDEX('Shared parameters'!$A$2:$A$200, MATCH($A10,'Shared parameters'!$B$2:$B$200,0) ), 'Parameter Categories'!$B$2:$G$200, 5, FALSE )="x", "Yes", "" ) ), "") -> Yes
A11: =INDEX(SharedParams[Name],ROW(B10)) -> DPP_AUR_Supplier | B11: =IFERROR( VLOOKUP( INDEX('Manual workflow'!$B$2:$B$200, MATCH($A11,'Manual workflow'!$A$2:$A$200,0) ), 'Built In Parameter groups'!$A$2:$C$200, 2, FALSE ), "") -> IdentityData | C11: =IFERROR( IF( VLOOKUP( INDEX('Shared parameters'!$A$2:$A$200, MATCH($A11,'Shared parameters'!$B$2:$B$200,0) ), 'Parameter Categories'!$B$2:$G$200, 6, FALSE )="x", "No", IF( VLOOKUP( INDEX('Shared parameters'!$A$2:$A$200, MATCH($A11,'Shared parameters'!$B$2:$B$200,0) ), 'Parameter Categories'!$B$2:$G$200, 5, FALSE )="x", "Yes", "" ) ), "") -> Yes
A12: =INDEX(SharedParams[Name],ROW(B11)) -> DPP_AUR_Supplier_URL | B12: =IFERROR( VLOOKUP( INDEX('Manual workflow'!$B$2:$B$200, MATCH($A12,'Manual workflow'!$A$2:$A$200,0) ), 'Built In Parameter groups'!$A$2:$C$200, 2, FALSE ), "") -> IdentityData | C12: =IFERROR( IF( VLOOKUP( INDEX('Shared parameters'!$A$2:$A$200, MATCH($A12,'Shared parameters'!$B$2:$B$200,0) ), 'Parameter Categories'!$B$2:$G$200, 6, FALSE )="x", "No", IF( VLOOKUP( INDEX('Shared parameters'!$A$2:$A$200, MATCH($A12,'Shared parameters'!$B$2:$B$200,0) ), 'Parameter Categories'!$B$2:$G$200, 5, FALSE )="x", "Yes", "" ) ), "") -> Yes
A13: =INDEX(SharedParams[Name],ROW(B12)) -> DPP_AUT_TransRoute | B13: =IFERROR( VLOOKUP( INDEX('Manual workflow'!$B$2:$B$200, MATCH($A13,'Manual workflow'!$A$2:$A$200,0) ), 'Built In Parameter groups'!$A$2:$C$200, 2, FALSE ), "") -> IdentityData | C13: =IFERROR( IF( VLOOKUP( INDEX('Shared parameters'!$A$2:$A$200, MATCH($A13,'Shared parameters'!$B$2:$B$200,0) ), 'Parameter Categories'!$B$2:$G$200, 6, FALSE )="x", "No", IF( VLOOKUP( INDEX('Shared parameters'!$A$2:$A$200, MATCH($A13,'Shared parameters'!$B$2:$B$200,0) ), 'Parameter Categories'!$B$2:$G$200, 5, FALSE )="x", "Yes", "" ) ), "") -> Yes
... A117: =INDEX(SharedParams[Name],ROW(B116)) -> DPP_COD_LCC_EUR | B117: =IFERROR( VLOOKUP( INDEX('Manual workflow'!$B$2:$B$200, MATCH($A117,'Manual workflow'!$A$2:$A$200,0) ), 'Built In Parameter groups'!$A$2:$C$200, 2, FALSE ), "") -> Data | C117: =IFERROR( IF( VLOOKUP( INDEX('Shared parameters'!$A$2:$A$200, MATCH($A117,'Shared parameters'!$B$2:$B$200,0) ), 'Parameter Categories'!$B$2:$G$200, 6, FALSE )="x", "No", IF( VLOOKUP( INDEX('Shared parameters'!$A$2:$A$200, MATCH($A117,'Shared parameters'!$B$2:$B$200,0) ), 'Parameter Categories'!$B$2:$G$200, 5, FALSE )="x", "Yes", "" ) ), "") -> No

Sheet Dynamo workflow (set formula)
A1: Shared Parameter Name | B1: Formula
A2: =INDEX(SharedParams[Name],ROW(B1)) -> DPP_AUT_Name | B2: =IFERROR( IF( ISNUMBER( VLOOKUP( INDEX('Shared parameters'!$A$2:$A$200, MATCH($A2,'Shared parameters'!$B$2:$B$200,0) ), 'Data Entry'!$A$2:$B$200, 2, FALSE ) ), VLOOKUP( INDEX('Shared parameters'!$A$2:$A$200, MATCH($A2,'Shared parameters'!$B$2:$B$200,0) ), 'Data Entry'!$A$2:$B$200, 2, FALSE ), """" & VLOOKUP( INDEX('Shared parameters'!$A$2:$A$200, MATCH($A2,'Shared parameters'!$B$2:$B$200,0) ), 'Data Entry'!$A$2:$B$200, 2, FALSE ) & """" ), "") -> "Hempstone"
A3: =INDEX(SharedParams[Name],ROW(B2)) -> DPP_AUT_ID | B3: =IFERROR( IF( ISNUMBER( VLOOKUP( INDEX('Shared parameters'!$A$2:$A$200, MATCH($A3,'Shared parameters'!$B$2:$B$200,0) ), 'Data Entry'!$A$2:$B$200, 2, FALSE ) ), VLOOKUP( INDEX('Shared parameters'!$A$2:$A$200, MATCH($A3,'Shared parameters'!$B$2:$B$200,0) ), 'Data Entry'!$A$2:$B$200, 2, FALSE ), """" & VLOOKUP( INDEX('Shared parameters'!$A$2:$A$200, MATCH($A3,'Shared parameters'!$B$2:$B$200,0) ), 'Data Entry'!$A$2:$B$200, 2, FALSE ) & """" ), "") -> "Z-17.25-1299"
A4: =INDEX(SharedParams[Name],ROW(B3)) -> DPP_AUT_Image | B4: =IFERROR( IF( ISNUMBER( VLOOKUP( INDEX('Shared parameters'!$A$2:$A$200, MATCH($A4,'Shared parameters'!$B$2:$B$200,0) ), 'Data Entry'!$A$2:$B$200, 2, FALSE ) ), VLOOKUP( INDEX('Shared parameters'!$A$2:$A$200, MATCH($A4,'Shared parameters'!$B$2:$B$200,0) ), 'Data Entry'!$A$2:$B$200, 2, FALSE ), """" & VLOOKUP( INDEX('Shared parameters'!$A$2:$A$200, MATCH($A4,'Shared parameters'!$B$2:$B$200,0) ), 'Data Entry'!$A$2:$B$200, 2, FALSE ) & """" ), "") -> "..\..\werner schönthaler\hanfsteine Sch├Ânthaler Kopie.png"
A5: =INDEX(SharedParams[Name],ROW(B4)) -> DPP_AUT_GUID | B5: =IFERROR( IF( ISNUMBER( VLOOKUP( INDEX('Shared parameters'!$A$2:$A$200, MATCH($A5,'Shared parameters'!$B$2:$B$200,0) ), 'Data Entry'!$A$2:$B$200, 2, FALSE ) ), VLOOKUP( INDEX('Shared parameters'!$A$2:$A$200, MATCH($A5,'Shared parameters'!$B$2:$B$200,0) ), 'Data Entry'!$A$2:$B$200, 2, FALSE ), """" & VLOOKUP( INDEX('Shared parameters'!$A$2:$A$200, MATCH($A5,'Shared parameters'!$B$2:$B$200,0) ), 'Data Entry'!$A$2:$B$200, 2, FALSE ) & """" ), "") -> ""
A6: =INDEX(SharedParams[Name],ROW(B5)) -> DPP_AUT_MaterialType | B6: =IFERROR( IF( ISNUMBER( VLOOKUP( INDEX('Shared parameters'!$A$2:$A$200, MATCH($A6,'Shared parameters'!$B$2:$B$200,0) ), 'Data Entry'!$A$2:$B$200, 2, FALSE ) ), VLOOKUP( INDEX('Shared parameters'!$A$2:$A$200, MATCH($A6,'Shared parameters'!$B$2:$B$200,0) ), 'Data Entry'!$A$2:$B$200, 2, FALSE ), """" & VLOOKUP( INDEX('Shared parameters'!$A$2:$A$200, MATCH($A6,'Shared parameters'!$B$2:$B$200,0) ), 'Data Entry'!$A$2:$B$200, 2, FALSE ) & """" ), "") -> "Type II"
A7: =INDEX(SharedParams[Name],ROW(B6)) -> DPP_AUT_Manufacturer | B7: =IFERROR( IF( ISNUMBER( VLOOKUP( INDEX('Shared parameters'!$A$2:$A$200, MATCH($A7,'Shared parameters'!$B$2:$B$200,0) ), 'Data Entry'!$A$2:$B$200, 2, FALSE ) ), VLOOKUP( INDEX('Shared parameters'!$A$2:$A$200, MATCH($A7,'Shared parameters'!$B$2:$B$200,0) ), 'Data Entry'!$A$2:$B$200, 2, FALSE ), """" & VLOOKUP( INDEX('Shared parameters'!$A$2:$A$200, MATCH($A7,'Shared parameters'!$B$2:$B$200,0) ), 'Data Entry'!$A$2:$B$200, 2, FALSE ) & """" ), "") -> "Schönthaler Bausteinwerk GmbH"
A8: =INDEX(SharedParams[Name],ROW(B7)) -> DPP_AUT_Manufacturer_URL | B8: =IFERROR( IF( ISNUMBER( VLOOKUP( INDEX('Shared parameters'!$A$2:$A$200, MATCH($A8,'Shared parameters'!$B$2:$B$200,0) ), 'Data Entry'!$A$2:$B$200, 2, FALSE ) ), VLOOKUP( INDEX('Shared parameters'!$A$2:$A$200, MATCH($A8,'Shared parameters'!$B$2:$B$200,0) ), 'Data Entry'!$A$2:$B$200, 2, FALSE ), """" & VLOOKUP( INDEX('Shared parameters'!$A$2:$A$200, MATCH($A8,'Shared parameters'!$B$2:$B$200,0) ), 'Data Entry'!$A$2:$B$200, 2, FALSE ) & """" ), "") -> "https://www.hanfstein.eu/"
A9: =INDEX(SharedParams[Name],ROW(B8)) -> DPP_AUT_Distribuitor | B9: =IFERROR( IF( ISNUMBER( VLOOKUP( INDEX('Shared parameters'!$A$2:$A$200, MATCH($A9,'Shared parameters'!$B$2:$B$200,0) ), 'Data Entry'!$A$2:$B$200, 2, FALSE ) ), VLOOKUP( INDEX('Shared parameters'!$A$2:$A$200, MATCH($A9,'Shared parameters'!$B$2:$B$200,0) ), 'Data Entry'!$A$2:$B$200, 2, FALSE ), """" & VLOOKUP( INDEX('Shared parameters'!$A$2:$A$200, MATCH($A9,'Shared parameters'!$B$2:$B$200,0) ), 'Data Entry'!$A$2:$B$200, 2, FALSE ) & """" ), "") -> "NA"
A10: =INDEX(SharedParams[Name],ROW(B9)) -> DPP_AUT_Distribuitor_URL | B10: =IFERROR( IF( ISNUMBER( VLOOKUP( INDEX('Shared parameters'!$A$2:$A$200, MATCH($A10,'Shared parameters'!$B$2:$B$200,0) ), 'Data Entry'!$A$2:$B$200, 2, FALSE ) ), VLOOKUP( INDEX('Shared parameters'!$A$2:$A$200, MATCH($A10,'Shared parameters'!$B$2:$B$200,0) ), 'Data Entry'!$A$2:$B$200, 2, FALSE ), """" & VLOOKUP( INDEX('Shared parameters'!$A$2:$A$200, MATCH($A10,'Shared parameters'!$B$2:$B$200,0) ), 'Data Entry'!$A$2:$B$200, 2, FALSE ) & """" ), "") -> "NA"
A11: =INDEX(SharedParams[Name],ROW(B10)) -> DPP_AUR_Supplier | B11: =IFERROR( IF( ISNUMBER( VLOOKUP( INDEX('Shared parameters'!$A$2:$A$200, MATCH($A11,'Shared parameters'!$B$2:$B$200,0) ), 'Data Entry'!$A$2:$B$200, 2, FALSE ) ), VLOOKUP( INDEX('Shared parameters'!$A$2:$A$200, MATCH($A11,'Shared parameters'!$B$2:$B$200,0) ), 'Data Entry'!$A$2:$B$200, 2, FALSE ), """" & VLOOKUP( INDEX('Shared parameters'!$A$2:$A$200, MATCH($A11,'Shared parameters'!$B$2:$B$200,0) ), 'Data Entry'!$A$2:$B$200, 2, FALSE ) & """" ), "") -> "NA"
A12: =INDEX(SharedParams[Name],ROW(B11)) -> DPP_AUR_Supplier_URL | B12: =IFERROR( IF( ISNUMBER( VLOOKUP( INDEX('Shared parameters'!$A$2:$A$200, MATCH($A12,'Shared parameters'!$B$2:$B$200,0) ), 'Data Entry'!$A$2:$B$200, 2, FALSE ) ), VLOOKUP( INDEX('Shared parameters'!$A$2:$A$200, MATCH($A12,'Shared parameters'!$B$2:$B$200,0) ), 'Data Entry'!$A$2:$B$200, 2, FALSE ), """" & VLOOKUP( INDEX('Shared parameters'!$A$2:$A$200, MATCH($A12,'Shared parameters'!$B$2:$B$200,0) ), 'Data Entry'!$A$2:$B$200, 2, FALSE ) & """" ), "") -> "NA"
A13: =INDEX(SharedParams[Name],ROW(B12)) -> DPP_AUT_TransRoute | B13: =IFERROR( IF( ISNUMBER( VLOOKUP( INDEX('Shared parameters'!$A$2:$A$200, MATCH($A13,'Shared parameters'!$B$2:$B$200,0) ), 'Data Entry'!$A$2:$B$200, 2, FALSE ) ), VLOOKUP( INDEX('Shared parameters'!$A$2:$A$200, MATCH($A13,'Shared parameters'!$B$2:$B$200,0) ), 'Data Entry'!$A$2:$B$200, 2, FALSE ), """" & VLOOKUP( INDEX('Shared parameters'!$A$2:$A$200, MATCH($A13,'Shared parameters'!$B$2:$B$200,0) ), 'Data Entry'!$A$2:$B$200, 2, FALSE ) & """" ), "") -> ""
... A117: =INDEX(SharedParams[Name],ROW(B116)) -> DPP_COD_LCC_EUR | B117: =IFERROR( IF( ISNUMBER( VLOOKUP( INDEX('Shared parameters'!$A$2:$A$200, MATCH($A117,'Shared parameters'!$B$2:$B$200,0) ), 'Data Entry'!$A$2:$B$200, 2, FALSE ) ), VLOOKUP( INDEX('Shared parameters'!$A$2:$A$200, MATCH($A117,'Shared parameters'!$B$2:$B$200,0) ), 'Data Entry'!$A$2:$B$200, 2, FALSE ), """" & VLOOKUP( INDEX('Shared parameters'!$A$2:$A$200, MATCH($A117,'Shared parameters'!$B$2:$B$200,0) ), 'Data Entry'!$A$2:$B$200, 2, FALSE ) & """" ), "") -> 47.376343

Sheet Pyrevit workflow
A1: Shared Parameter Name | B1: BIP Name | C1: Instance | D1: Formula
A2: =INDEX(SharedParams[Name],ROW(B1)) -> DPP_AUT_Name | B2: =IFERROR( VLOOKUP( INDEX('Manual workflow'!$B$2:$B$200, MATCH($A2,'Manual workflow'!$A$2:$A$200,0) ), 'Built In Parameter groups'!$A$2:$C$200, 3, FALSE ), "") -> PG_IDENTITY_DATA | C2: =IFERROR(IF(VLOOKUP(INDEX('Shared parameters'!$A$2:$A$200,MATCH($A2,'Shared parameters'!$B$2:$B$200,0)),'Parameter Categories'!$B$2:$G$200,6,FALSE)="x","No",IF(VLOOKUP(INDEX('Shared parameters'!$A$2:$A$200,MATCH($A2,'Shared parameters'!$B$2:$B$200,0)),'Parameter Categories'!$B$2:$G$200,5,FALSE)="x","Yes","")),"") -> No | D2: =IFERROR( IF( ISNUMBER( VLOOKUP( INDEX('Shared parameters'!$A$2:$A$200, MATCH($A2,'Shared parameters'!$B$2:$B$200,0) ), 'Data Entry'!$A$2:$B$200, 2, FALSE ) ), VLOOKUP( INDEX('Shared parameters'!$A$2:$A$200, MATCH($A2,'Shared parameters'!$B$2:$B$200,0) ), 'Data Entry'!$A$2:$B$200, 2, FALSE ), """" & VLOOKUP( INDEX('Shared parameters'!$A$2:$A$200, MATCH($A2,'Shared parameters'!$B$2:$B$200,0) ), 'Data Entry'!$A$2:$B$200, 2, FALSE ) & """" ), "") -> "Hempstone"
A3: =INDEX(SharedParams[Name],ROW(B2)) -> DPP_AUT_ID | B3: =IFERROR( VLOOKUP( INDEX('Manual workflow'!$B$2:$B$200, MATCH($A3,'Manual workflow'!$A$2:$A$200,0) ), 'Built In Parameter groups'!$A$2:$C$200, 3, FALSE ), "") -> PG_IDENTITY_DATA | C3: =IFERROR( IF( VLOOKUP( INDEX('Shared parameters'!$A$2:$A$200, MATCH($A3,'Shared parameters'!$B$2:$B$200,0) ), 'Parameter Categories'!$B$2:$G$200, 6, FALSE )="x", "No", IF( VLOOKUP( INDEX('Shared parameters'!$A$2:$A$200, MATCH($A3,'Shared parameters'!$B$2:$B$200,0) ), 'Parameter Categories'!$B$2:$G$200, 5, FALSE )="x", "Yes", "" ) ), "") -> No | D3: =IFERROR( IF( ISNUMBER( VLOOKUP( INDEX('Shared parameters'!$A$2:$A$200, MATCH($A3,'Shared parameters'!$B$2:$B$200,0) ), 'Data Entry'!$A$2:$B$200, 2, FALSE ) ), VLOOKUP( INDEX('Shared parameters'!$A$2:$A$200, MATCH($A3,'Shared parameters'!$B$2:$B$200,0) ), 'Data Entry'!$A$2:$B$200, 2, FALSE ), """" & VLOOKUP( INDEX('Shared parameters'!$A$2:$A$200, MATCH($A3,'Shared parameters'!$B$2:$B$200,0) ), 'Data Entry'!$A$2:$B$200, 2, FALSE ) & """" ), "") -> "Z-17.25-1299"
A4: =INDEX(SharedParams[Name],ROW(B3)) -> DPP_AUT_Image | B4: =IFERROR( VLOOKUP( INDEX('Manual workflow'!$B$2:$B$200, MATCH($A4,'Manual workflow'!$A$2:$A$200,0) ), 'Built In Parameter groups'!$A$2:$C$200, 3, FALSE ), "") -> PG_IDENTITY_DATA | C4: =IFERROR( IF( VLOOKUP( INDEX('Shared parameters'!$A$2:$A$200, MATCH($A4,'Shared parameters'!$B$2:$B$200,0) ), 'Parameter Categories'!$B$2:$G$200, 6, FALSE )="x", "No", IF( VLOOKUP( INDEX('Shared parameters'!$A$2:$A$200, MATCH($A4,'Shared parameters'!$B$2:$B$200,0) ), 'Parameter Categories'!$B$2:$G$200, 5, FALSE )="x", "Yes", "" ) ), "") -> Yes | D4: =IFERROR( IF( ISNUMBER( VLOOKUP( INDEX('Shared parameters'!$A$2:$A$200, MATCH($A4,'Shared parameters'!$B$2:$B$200,0) ), 'Data Entry'!$A$2:$B$200, 2, FALSE ) ), VLOOKUP( INDEX('Shared parameters'!$A$2:$A$200, MATCH($A4,'Shared parameters'!$B$2:$B$200,0) ), 'Data Entry'!$A$2:$B$200, 2, FALSE ), """" & VLOOKUP( INDEX('Shared parameters'!$A$2:$A$200, MATCH($A4,'Shared parameters'!$B$2:$B$200,0) ), 'Data Entry'!$A$2:$B$200, 2, FALSE ) & """" ), "") -> "..\..\werner schönthaler\hanfsteine Sch├Ânthaler Kopie.png"
A5: =INDEX(SharedParams[Name],ROW(B4)) -> DPP_AUT_GUID | B5: =IFERROR( VLOOKUP( INDEX('Manual workflow'!$B$2:$B$200, MATCH($A5,'Manual workflow'!$A$2:$A$200,0) ), 'Built In Parameter groups'!$A$2:$C$200, 3, FALSE ), "") -> PG_IDENTITY_DATA | C5: =IFERROR( IF( VLOOKUP( INDEX('Shared parameters'!$A$2:$A$200, MATCH($A5,'Shared parameters'!$B$2:$B$200,0) ), 'Parameter Categories'!$B$2:$G$200, 6, FALSE )="x", "No", IF( VLOOKUP( INDEX('Shared parameters'!$A$2:$A$200, MATCH($A5,'Shared parameters'!$B$2:$B$200,0) ), 'Parameter Categories'!$B$2:$G$200, 5, FALSE )="x", "Yes", "" ) ), "") -> No | D5: =IFERROR( IF( ISNUMBER( VLOOKUP( INDEX('Shared parameters'!$A$2:$A$200, MATCH($A5,'Shared parameters'!$B$2:$B$200,0) ), 'Data Entry'!$A$2:$B$200, 2, FALSE ) ), VLOOKUP( INDEX('Shared parameters'!$A$2:$A$200, MATCH($A5,'Shared parameters'!$B$2:$B$200,0) ), 'Data Entry'!$A$2:$B$200, 2, FALSE ), """" & VLOOKUP( INDEX('Shared parameters'!$A$2:$A$200, MATCH($A5,'Shared parameters'!$B$2:$B$200,0) ), 'Data Entry'!$A$2:$B$200, 2, FALSE ) & """" ), "") -> ""
A6: =INDEX(SharedParams[Name],ROW(B5)) -> DPP_AUT_MaterialType | B6: =IFERROR( VLOOKUP( INDEX('Manual workflow'!$B$2:$B$200, MATCH($A6,'Manual workflow'!$A$2:$A$200,0) ), 'Built In Parameter groups'!$A$2:$C$200, 3, FALSE ), "") -> PG_MATERIALS | C6: =IFERROR( IF( VLOOKUP( INDEX('Shared parameters'!$A$2:$A$200, MATCH($A6,'Shared parameters'!$B$2:$B$200,0) ), 'Parameter Categories'!$B$2:$G$200, 6, FALSE )="x", "No", IF( VLOOKUP( INDEX('Shared parameters'!$A$2:$A$200, MATCH($A6,'Shared parameters'!$B$2:$B$200,0) ), 'Parameter Categories'!$B$2:$G$200, 5, FALSE )="x", "Yes", "" ) ), "") -> No | D6: =IFERROR( IF( ISNUMBER( VLOOKUP( INDEX('Shared parameters'!$A$2:$A$200, MATCH($A6,'Shared parameters'!$B$2:$B$200,0) ), 'Data Entry'!$A$2:$B$200, 2, FALSE ) ), VLOOKUP( INDEX('Shared parameters'!$A$2:$A$200, MATCH($A6,'Shared parameters'!$B$2:$B$200,0) ), 'Data Entry'!$A$2:$B$200, 2, FALSE ), """" & VLOOKUP( INDEX('Shared parameters'!$A$2:$A$200, MATCH($A6,'Shared parameters'!$B$2:$B$200,0) ), 'Data Entry'!$A$2:$B$200, 2, FALSE ) & """" ), "") -> "Type II"
A7: =INDEX(SharedParams[Name],ROW(B6)) -> DPP_AUT_Manufacturer | B7: =IFERROR( VLOOKUP( INDEX('Manual workflow'!$B$2:$B$200, MATCH($A7,'Manual workflow'!$A$2:$A$200,0) ), 'Built In Parameter groups'!$A$2:$C$200, 3, FALSE ), "") -> PG_IDENTITY_DATA | C7: =IFERROR( IF( VLOOKUP( INDEX('Shared parameters'!$A$2:$A$200, MATCH($A7,'Shared parameters'!$B$2:$B$200,0) ), 'Parameter Categories'!$B$2:$G$200, 6, FALSE )="x", "No", IF( VLOOKUP( INDEX('Shared parameters'!$A$2:$A$200, MATCH($A7,'Shared parameters'!$B$2:$B$200,0) ), 'Parameter Categories'!$B$2:$G$200, 5, FALSE )="x", "Yes", "" ) ), "") -> No | D7: =IFERROR( IF( ISNUMBER( VLOOKUP( INDEX('Shared parameters'!$A$2:$A$200, MATCH($A7,'Shared parameters'!$B$2:$B$200,0) ), 'Data Entry'!$A$2:$B$200, 2, FALSE ) ), VLOOKUP( INDEX('Shared parameters'!$A$2:$A$200, MATCH($A7,'Shared parameters'!$B$2:$B$200,0) ), 'Data Entry'!$A$2:$B$200, 2, FALSE ), """" & VLOOKUP( INDEX('Shared parameters'!$A$2:$A$200, MATCH($A7,'Shared parameters'!$B$2:$B$200,0) ), 'Data Entry'!$A$2:$B$200, 2, FALSE ) & """" ), "") -> "Schönthaler Bausteinwerk GmbH"
A8: =INDEX(SharedParams[Name],ROW(B7)) -> DPP_AUT_Manufacturer_URL | B8: =IFERROR( VLOOKUP( INDEX('Manual workflow'!$B$2:$B$200, MATCH($A8,'Manual workflow'!$A$2:$A$200,0) ), 'Built In Parameter groups'!$A$2:$C$200, 3, FALSE ), "") -> PG_IDENTITY_DATA | C8: =IFERROR( IF( VLOOKUP( INDEX('Shared parameters'!$A$2:$A$200, MATCH($A8,'Shared parameters'!$B$2:$B$200,0) ), 'Parameter Categories'!$B$2:$G$200, 6, FALSE )="x", "No", IF( VLOOKUP( INDEX('Shared parameters'!$A$2:$A$200, MATCH($A8,'Shared parameters'!$B$2:$B$200,0) ), 'Parameter Categories'!$B$2:$G$200, 5, FALSE )="x", "Yes", "" ) ), "") -> No | D8: =IFERROR( IF( ISNUMBER( VLOOKUP( INDEX('Shared parameters'!$A$2:$A$200, MATCH($A8,'Shared parameters'!$B$2:$B$200,0) ), 'Data Entry'!$A$2:$B$200, 2, FALSE ) ), VLOOKUP( INDEX('Shared parameters'!$A$2:$A$200, MATCH($A8,'Shared parameters'!$B$2:$B$200,0) ), 'Data Entry'!$A$2:$B$200, 2, FALSE ), """" & VLOOKUP( INDEX('Shared parameters'!$A$2:$A$200, MATCH($A8,'Shared parameters'!$B$2:$B$200,0) ), 'Data Entry'!$A$2:$B$200, 2, FALSE ) & """" ), "") -> "https://www.hanfstein.eu/"
A9: =INDEX(SharedParams[Name],ROW(B8)) -> DPP_AUT_Distribuitor | B9: =IFERROR( VLOOKUP( INDEX('Manual workflow'!$B$2:$B$200, MATCH($A9,'Manual workflow'!$A$2:$A$200,0) ), 'Built In Parameter groups'!$A$2:$C$200, 3, FALSE ), "") -> PG_IDENTITY_DATA | C9: =IFERROR( IF( VLOOKUP( INDEX('Shared parameters'!$A$2:$A$200, MATCH($A9,'Shared parameters'!$B$2:$B$200,0) ), 'Parameter Categories'!$B$2:$G$200, 6, FALSE )="x", "No", IF( VLOOKUP( INDEX('Shared parameters'!$A$2:$A$200, MATCH($A9,'Shared parameters'!$B$2:$B$200,0) ), 'Parameter Categories'!$B$2:$G$200, 5, FALSE )="x", "Yes", "" ) ), "") -> Yes | D9: =IFERROR( IF( ISNUMBER( VLOOKUP( INDEX('Shared parameters'!$A$2:$A$200, MATCH($A9,'Shared parameters'!$B$2:$B$200,0) ), 'Data Entry'!$A$2:$B$200, 2, FALSE ) ), VLOOKUP( INDEX('Shared parameters'!$A$2:$A$200, MATCH($A9,'Shared parameters'!$B$2:$B$200,0) ), 'Data Entry'!$A$2:$B$200, 2, FALSE ), """" & VLOOKUP( INDEX('Shared parameters'!$A$2:$A$200, MATCH($A9,'Shared parameters'!$B$2:$B$200,0) ), 'Data Entry'!$A$2:$B$200, 2, FALSE ) & """" ), "") -> "NA"
A10: =INDEX(SharedParams[Name],ROW(B9)) -> DPP_AUT_Distribuitor_URL | B10: =IFERROR( VLOOKUP( INDEX('Manual workflow'!$B$2:$B$200, MATCH($A10,'Manual workflow'!$A$2:$A$200,0) ), 'Built In Parameter groups'!$A$2:$C$200, 3, FALSE ), "") -> PG_IDENTITY_DATA | C10: =IFERROR( IF( VLOOKUP( INDEX('Shared parameters'!$A$2:$A$200, MATCH($A10,'Shared parameters'!$B$2:$B$200,0) ), 'Parameter Categories'!$B$2:$G$200, 6, FALSE )="x", "No", IF( VLOOKUP( INDEX('Shared parameters'!$A$2:$A$200, MATCH($A10,'Shared parameters'!$B$2:$B$200,0) ), 'Parameter Categories'!$B$2:$G$200, 5, FALSE )="x", "Yes", "" ) ), "") -> Yes | D10: =IFERROR( IF( ISNUMBER( VLOOKUP( INDEX('Shared parameters'!$A$2:$A$200, MATCH($A10,'Shared parameters'!$B$2:$B$200,0) ), 'Data Entry'!$A$2:$B$200, 2, FALSE ) ), VLOOKUP( INDEX('Shared parameters'!$A$2:$A$200, MATCH($A10,'Shared parameters'!$B$2:$B$200,0) ), 'Data Entry'!$A$2:$B$200, 2, FALSE ), """" & VLOOKUP( INDEX('Shared parameters'!$A$2:$A$200, MATCH($A10,'Shared parameters'!$B$2:$B$200,0) ), 'Data Entry'!$A$2:$B$200, 2, FALSE ) & """" ), "") -> "NA"
A11: =INDEX(SharedParams[Name],ROW(B10)) -> DPP_AUR_Supplier | B11: =IFERROR( VLOOKUP( INDEX('Manual workflow'!$B$2:$B$200, MATCH($A11,'Manual workflow'!$A$2:$A$200,0) ), 'Built In Parameter groups'!$A$2:$C$200, 3, FALSE ), "") -> PG_IDENTITY_DATA | C11: =IFERROR( IF( VLOOKUP( INDEX('Shared parameters'!$A$2:$A$200, MATCH($A11,'Shared parameters'!$B$2:$B$200,0) ), 'Parameter Categories'!$B$2:$G$200, 6, FALSE )="x", "No", IF( VLOOKUP( INDEX('Shared parameters'!$A$2:$A$200, MATCH($A11,'Shared parameters'!$B$2:$B$200,0) ), 'Parameter Categories'!$B$2:$G$200, 5, FALSE )="x", "Yes", "" ) ), "") -> Yes | D11: =IFERROR( IF( ISNUMBER( VLOOKUP( INDEX('Shared parameters'!$A$2:$A$200, MATCH($A11,'Shared parameters'!$B$2:$B$200,0) ), 'Data Entry'!$A$2:$B$200, 2, FALSE ) ), VLOOKUP( INDEX('Shared parameters'!$A$2:$A$200, MATCH($A11,'Shared parameters'!$B$2:$B$200,0) ), 'Data Entry'!$A$2:$B$200, 2, FALSE ), """" & VLOOKUP( INDEX('Shared parameters'!$A$2:$A$200, MATCH($A11,'Shared parameters'!$B$2:$B$200,0) ), 'Data Entry'!$A$2:$B$200, 2, FALSE ) & """" ), "") -> "NA"
A12: =INDEX(SharedParams[Name],ROW(B11)) -> DPP_AUR_Supplier_URL | B12: =IFERROR( VLOOKUP( INDEX('Manual workflow'!$B$2:$B$200, MATCH($A12,'Manual workflow'!$A$2:$A$200,0) ), 'Built In Parameter groups'!$A$2:$C$200, 3, FALSE ), "") -> PG_IDENTITY_DATA | C12: =IFERROR( IF( VLOOKUP( INDEX('Shared parameters'!$A$2:$A$200, MATCH($A12,'Shared parameters'!$B$2:$B$200,0) ), 'Parameter Categories'!$B$2:$G$200, 6, FALSE )="x", "No", IF( VLOOKUP( INDEX('Shared parameters'!$A$2:$A$200, MATCH($A12,'Shared parameters'!$B$2:$B$200,0) ), 'Parameter Categories'!$B$2:$G$200, 5, FALSE )="x", "Yes", "" ) ), "") -> Yes | D12: =IFERROR( IF( ISNUMBER( VLOOKUP( INDEX('Shared parameters'!$A$2:$A$200, MATCH($A12,'Shared parameters'!$B$2:$B$200,0) ), 'Data Entry'!$A$2:$B$200, 2, FALSE ) ), VLOOKUP( INDEX('Shared parameters'!$A$2:$A$200, MATCH($A12,'Shared parameters'!$B$2:$B$200,0) ), 'Data Entry'!$A$2:$B$200, 2, FALSE ), """" & VLOOKUP( INDEX('Shared parameters'!$A$2:$A$200, MATCH($A12,'Shared parameters'!$B$2:$B$200,0) ), 'Data Entry'!$A$2:$B$200, 2, FALSE ) & """" ), "") -> "NA"
A13: =INDEX(SharedParams[Name],ROW(B12)) -> DPP_AUT_TransRoute | B13: =IFERROR( VLOOKUP( INDEX('Manual workflow'!$B$2:$B$200, MATCH($A13,'Manual workflow'!$A$2:$A$200,0) ), 'Built In Parameter groups'!$A$2:$C$200, 3, FALSE ), "") -> PG_IDENTITY_DATA | C13: =IFERROR( IF( VLOOKUP( INDEX('Shared parameters'!$A$2:$A$200, MATCH($A13,'Shared parameters'!$B$2:$B$200,0) ), 'Parameter Categories'!$B$2:$G$200, 6, FALSE )="x", "No", IF( VLOOKUP( INDEX('Shared parameters'!$A$2:$A$200, MATCH($A13,'Shared parameters'!$B$2:$B$200,0) ), 'Parameter Categories'!$B$2:$G$200, 5, FALSE )="x", "Yes", "" ) ), "") -> Yes | D13: =IFERROR( IF( ISNUMBER( VLOOKUP( INDEX('Shared parameters'!$A$2:$A$200, MATCH($A13,'Shared parameters'!$B$2:$B$200,0) ), 'Data Entry'!$A$2:$B$200, 2, FALSE ) ), VLOOKUP( INDEX('Shared parameters'!$A$2:$A$200, MATCH($A13,'Shared parameters'!$B$2:$B$200,0) ), 'Data Entry'!$A$2:$B$200, 2, FALSE ), """" & VLOOKUP( INDEX('Shared parameters'!$A$2:$A$200, MATCH($A13,'Shared parameters'!$B$2:$B$200,0) ), 'Data Entry'!$A$2:$B$200, 2, FALSE ) & """" ), "") -> ""
A14: =INDEX(SharedParams[Name],ROW(B13)) -> DPP_AUT_Traceability | B14: =IFERROR( VLOOKUP( INDEX('Manual workflow'!$B$2:$B$200, MATCH($A14,'Manual workflow'!$A$2:$A$200,0) ), 'Built In Parameter groups'!$A$2:$C$200, 3, FALSE ), "") -> PG_IDENTITY_DATA | C14: =IFERROR( IF( VLOOKUP( INDEX('Shared parameters'!$A$2:$A$200, MATCH($A14,'Shared parameters'!$B$2:$B$200,0) ), 'Parameter Categories'!$B$2:$G$200, 6, FALSE )="x", "No", IF( VLOOKUP( INDEX('Shared parameters'!$A$2:$A$200, MATCH($A14,'Shared parameters'!$B$2:$B$200,0) ), 'Parameter Categories'!$B$2:$G$200, 5, FALSE )="x", "Yes", "" ) ), "") -> No | D14: =IFERROR( IF( ISNUMBER( VLOOKUP( INDEX('Shared parameters'!$A$2:$A$200, MATCH($A14,'Shared parameters'!$B$2:$B$200,0) ), 'Data Entry'!$A$2:$B$200, 2, FALSE ) ), VLOOKUP( INDEX('Shared parameters'!$A$2:$A$200, MATCH($A14,'Shared parameters'!$B$2:$B$200,0) ), 'Data Entry'!$A$2:$B$200, 2, FALSE ), """" & VLOOKUP( INDEX('Shared parameters'!$A$2:$A$200, MATCH($A14,'Shared parameters'!$B$2:$B$200,0) ), 'Data Entry'!$A$2:$B$200, 2, FALSE ) & """" ), "") -> "a1b2c3d4-e5f6-7890-1234-567890abcdef"
... A117: =INDEX(SharedParams[Name],ROW(B116)) -> DPP_COD_LCC_EUR | B117: =IFERROR( VLOOKUP( INDEX('Manual workflow'!$B$2:$B$200, MATCH($A117,'Manual workflow'!$A$2:$A$200,0) ), 'Built In Parameter groups'!$A$2:$C$200, 3, FALSE ), "") -> PG_DATA | C117: =IFERROR( IF( VLOOKUP( INDEX('Shared parameters'!$A$2:$A$200, MATCH($A117,'Shared parameters'!$B$2:$B$200,0) ), 'Parameter Categories'!$B$2:$G$200, 6, FALSE )="x", "No", IF( VLOOKUP( INDEX('Shared parameters'!$A$2:$A$200, MATCH($A117,'Shared parameters'!$B$2:$B$200,0) ), 'Parameter Categories'!$B$2:$G$200, 5, FALSE )="x", "Yes", "" ) ), "") -> No | D117: =IFERROR( IF( ISNUMBER( VLOOKUP( INDEX('Shared parameters'!$A$2:$A$200, MATCH($A117,'Shared parameters'!$B$2:$B$200,0) ), 'Data Entry'!$A$2:$B$200, 2, FALSE ) ), VLOOKUP( INDEX('Shared parameters'!$A$2:$A$200, MATCH($A117,'Shared parameters'!$B$2:$B$200,0) ), 'Data Entry'!$A$2:$B$200, 2, FALSE ), """" & VLOOKUP( INDEX('Shared parameters'!$A$2:$A$200, MATCH($A117,'Shared parameters'!$B$2:$B$200,0) ), 'Data Entry'!$A$2:$B$200, 2, FALSE ) & """" ), "") -> 47.376343

Sheet Parameter mapping
A1: Shared Parameter Name | B1: Revit Built-In Parameter | C1: IFC Standard Pset | D1: Custom Pset (DPP) | E1: Property Type | F1: Ontology property | G1: URI
A2: =INDEX(SharedParams[Name],ROW(B1)) -> DPP_AUT_Name | B2: Name | C2: IfcRoot | E2: String | F2: PROPS:hasGlobalIdIfcRoot
A3: =INDEX(SharedParams[Name],ROW(B2)) -> DPP_AUT_ID | B3: Model | C3: IfcRoot | E3: Identifier | F3: SCHEMA:label/name
A4: =INDEX(SharedParams[Name],ROW(B3)) -> DPP_AUT_Image | B4: Type Image | C4: IfcDocumentReference | F4: SCHEMA:image
A5: =INDEX(SharedParams[Name],ROW(B4)) -> DPP_AUT_GUID | B5: Element GUID | C5: IfcRoot | E5: Identifier | F5: PROPS:hasGUID
A6: =INDEX(SharedParams[Name],ROW(B5)) -> DPP_AUT_MaterialType | B6: MATERIAL_ID_PARAM | C6: IfcMaterial | E6: String | F6: SCHEMA:model
A7: =INDEX(SharedParams[Name],ROW(B6)) -> DPP_AUT_Manufacturer | B7: Manufacturer | C7: Pset_ManufacturerTypeInformation | E7: String | F7: BPM:manufaturer
A8: =INDEX(SharedParams[Name],ROW(B7)) -> DPP_AUT_Manufacturer_URL | B8: ALL_MODEL_URL | C8: Pset_ManufacturerTypeInformation | E8: String | F8: SCHEMA:url
A9: =INDEX(SharedParams[Name],ROW(B8)) -> DPP_AUT_Distribuitor | C9: Custom Pset | D9: Pset_DDPHempcrete | E9: String | F9: SCHEMA:distribuitor
A10: =INDEX(SharedParams[Name],ROW(B9)) -> DPP_AUT_Distribuitor_URL | C10: Custom Pset | D10: Pset_DDPHempcrete | E10: String | F10: SCHEMA:url
A11: =INDEX(SharedParams[Name],ROW(B10)) -> DPP_AUR_Supplier | C11: Custom Pset | D11: Pset_DDPHempcrete | E11: String | F11: SCHEMA:supplier
A12: =INDEX(SharedParams[Name],ROW(B11)) -> DPP_AUR_Supplier_URL | C12: Custom Pset | D12: Pset_DDPHempcrete | E12: String | F12: SCHEMA:url
A13: =INDEX(SharedParams[Name],ROW(B12)) -> DPP_AUT_TransRoute | C13: Custom Pset | D13: Pset_DDPHempcrete | E13: String | F13: PROV:wasderivedfrom
A14: =INDEX(SharedParams[Name],ROW(B13)) -> DPP_AUT_Traceability | C14: Custom Pset | D14: Pset_DDPHempcrete | E14: Identifier | F14: PROV:wasAttributedTo
A15: =INDEX(SharedParams[Name],ROW(B14)) -> DPP_AUT_Origin | C15: Pset_ManufacturerTypeInformation | E15: String | F15: PROV:wasGeneratedby/location
A16: =INDEX(SharedParams[Name],ROW(B15)) -> DPP_AUT_Version | B16: Type Mark | C16: Pset_ManufacturerTypeInformation | E16: String
A17: =INDEX(SharedParams[Name],ROW(B16)) -> DPP_MAT_Material | B17: Material.Name | C17: IfcMaterial | E17: String | F17: SCHEMA:material
A18: =INDEX(SharedParams[Name],ROW(B17)) -> DPP_MAT_Components | C18: Custom Pset | D18: Pset_DDPHempcrete | E18: String | F18: BPM:hasMaterial
A19: =INDEX(SharedParams[Name],ROW(B18)) -> DPP_MAT_Composition | B19: ALL_MODEL_DESCRIPTION | C19: IfcMaterial | E19: String | F19: BPM:materialcomposition
A20: =INDEX(SharedParams[Name],ROW(B19)) -> DPP_AUT_TypeDimension | B20: TYPE_NAME | C20: IfcRoot | E20: String | F20: SCHEMA:additionaltype
A21: =INDEX(SharedParams[Name],ROW(B20)) -> DPP_DIM_Height_mm | B21: Height | C21: IfcElementQuantity | E21: Length | F21: QUDT:height/value
A22: =INDEX(SharedParams[Name],ROW(B21)) -> DPP_DIM_Length_mm | B22: Length | C22: IfcElementQuantity | E22: Length | F22: QUDT:lenght/value
A23: =INDEX(SharedParams[Name],ROW(B22)) -> DPP_DIM_Width_mm | B23: Width | C23: IfcElementQuantity | E23: Length | F23: QUDT:width/value
A24: =INDEX(SharedParams[Name],ROW(B23)) -> DPP_DIM_Volume_m3 | B24: Volume | C24: IfcElementQuantity | E24: Volume | F24: QUDT:volume/value
A25: =INDEX(SharedParams[Name],ROW(B24)) -> DPP_DAT_DryDensity_kgm3 | B25: Dry Density | C25: Pset_MaterialCommon | E25: Real | F25: QUDT:density/value
A26: =INDEX(SharedParams[Name],ROW(B25)) -> DPP_DAT_EqDensity_kgm3 | B26: Equilibrium Density | C26: Pset_MaterialCommon | E26: Real | F26: QUDT:density/value
A27: =INDEX(SharedParams[Name],ROW(B26)) -> DPP_DAT_Weight_kg | B27: Weight | C27: Pset_MaterialCommon | E27: Mass | F27: QUDT:weight/value
A28: =INDEX(SharedParams[Name],ROW(B27)) -> DPP_DAT_CompressiveStrenght_Mpa | B28: Compressive Strenght | C28: Pset_MaterialCommon | E28: Real | F28: PROPS:compressivestrength
A29: =INDEX(SharedParams[Name],ROW(B28)) -> DPP_DAT_ShearStrenght_Mpa | B29: PHY_MATERIAL_PARAM_STRUCTURAL | C29: Pset_MaterialCommon | E29: Real | F29: PROPS:tensilestrength
A30: =INDEX(SharedParams[Name],ROW(B29)) -> DPP_DAT_ThermalConductivity_WmK | B30: Thermal Conductivity | C30: Pset_MaterialCommon | E30: Real | F30: PROPS:thermalconductivity
A31: =INDEX(SharedParams[Name],ROW(B30)) -> DPP_DAT_Uvalue_Wm2K | B31: THERMAL_MATERIAL_PARAM | C31: Pset_MaterialCommon | E31: Real
A32: =INDEX(SharedParams[Name],ROW(B31)) -> DPP_DAT_SpeHeatCap_JkgK | B32: THERMAL_MATERIAL_PARAM | C32: Pset_MaterialCommon | E32: Real | F32: PROPS:tensilestrength
A33: =INDEX(SharedParams[Name],ROW(B32)) -> DPP_DAT_PhaseShift_Hours | C33: Pset_MaterialCommon | E33: Real | F33: PROPS:phasePermeability
A34: =INDEX(SharedParams[Name],ROW(B33)) -> DPP_DAT_MoistureBuffer_m2%HR | C34: Custom Pset | D34: Pset_DDPHempcrete | E34: Real | F34: DPP:moistureBuffer
A35: =INDEX(SharedParams[Name],ROW(B34)) -> DPP_DAT_VaporDiffμ_wet | C35: Pset_MaterialHygroscopic | E35: Real | F35: PROPS:vaporPermeability
A36: =INDEX(SharedParams[Name],ROW(B35)) -> DPP_DAT_VaporDiffμ_dry | C36: Pset_MaterialHygroscopic | E36: Real | F36: PROPS:vaporPermeability
A37: =INDEX(SharedParams[Name],ROW(B36)) -> DPP_DAT_VaporAbsorption | C37: Pset_MaterialHygroscopic | E37: Real | F37: PROPS:porosity
A38: =INDEX(SharedParams[Name],ROW(B37)) -> DPP_DAT_StandarCompliance | B38: ALL_MODEL_TYPE_COMMENTS | C38: IfcDocumentReference | E38: Boolean | F38: SCHEMA:comformsTo
A39: =INDEX(SharedParams[Name],ROW(B38)) -> DPP_CIR_ConnectionType | C39: Custom Pset | D39: Pset_DDPHempcrete | E39: String
A40: =INDEX(SharedParams[Name],ROW(B39)) -> DPP_CIR_ConnectionScore | C40: Custom Pset | D40: Pset_DDPHempcrete | E40: Real
...

Sheet Final Dataset
A1: Parameter | B1: Data | C1: Unit | D1: Range
A2: =INDEX(SharedParams[Name],ROW(B1)) -> DPP_AUT_Name | B2: =IFERROR( VLOOKUP( INDEX('Shared parameters'!$A$2:$A$200, MATCH($A2,'Shared parameters'!$B$2:$B$200,0) ), 'Data Entry'!$A$2:$B$200, 2, FALSE ), "") -> Hempstone | C2: =IFERROR( VLOOKUP( INDEX('Shared parameters'!$A$2:$A$200, MATCH($A2,'Shared parameters'!$B$2:$B$200,0) ), 'Data Entry'!$A$2:$C$200, 3, FALSE ), "") -> — | D2: =IFERROR( VLOOKUP( INDEX('Shared parameters'!$A$2:$A$200, MATCH($A2,'Shared parameters'!$B$2:$B$200,0) ), 'Data Entry'!$A$2:$D$200, 4, FALSE ), "") -> —
A3: =INDEX(SharedParams[Name],ROW(B2)) -> DPP_AUT_ID | B3: =IFERROR( VLOOKUP( INDEX('Shared parameters'!$A$2:$A$200, MATCH($A3,'Shared parameters'!$B$2:$B$200,0) ), 'Data Entry'!$A$2:$B$200, 2, FALSE ), "") -> Z-17.25-1299 | C3: =IFERROR( VLOOKUP( INDEX('Shared parameters'!$A$2:$A$200, MATCH($A3,'Shared parameters'!$B$2:$B$200,0) ), 'Data Entry'!$A$2:$C$200, 3, FALSE ), "") -> ID | D3: =IFERROR( VLOOKUP( INDEX('Shared parameters'!$A$2:$A$200, MATCH($A3,'Shared parameters'!$B$2:$B$200,0) ), 'Data Entry'!$A$2:$D$200, 4, FALSE ), "") -> —
