Workbook

Sheet 1 Data Material DPP
A1: Category | B1: Parameter | C1: Data | D1: Unit | E1: Range | F1: Source
A2: 1. Identification and General Information | B2: ='[1]DPP Categories'!B2 -> Product Name | C2: Hempstone | D2: — | E2: — | F2: Technical data sheet 06/2025
B3: ='[1]DPP Categories'!B3 -> Product ID | C3: Z-17.25-1299 | D3: ID | E3: — | F3: German general type approval
B4: ='[1]DPP Categories'!B4 -> Object number | D4: GUID | E4: — | F4: BIM parameter
B5: ='[1]DPP Categories'!B5 -> Material Type | D5: — | E5: —
B6: ='[1]DPP Categories'!B6 -> Manufacturer | C6: Schönthaler Bausteinwerk GmbH | D6: — | E6: — | F6: German general type approval
B7: ='[1]DPP Categories'!B10 -> Traceability ID | E7: —
B8: ='[1]DPP Categories'!B11 -> Origin | C8: 39020 Oris (BZ) | D8: — | E8: —
B9: ='[1]DPP Categories'!B12 -> Version number | C9: HKZ 335 | D9: No. | E9: HKZ 335 - HKZ 360 | F9: German general type approval
A10: 2. Physical and Technical Properties | B10: ='[1]DPP Categories'!B13 -> Material | C10: Infill masonry made of hemp stones | D10: — | E10: — | F10: BIM parameter
B11: ='[1]DPP Categories'!B15 -> Composition | C11: Hemp-lime composite | D11: — | F11: Technical data sheet 06/2025
B12: ='[1]DPP Categories'!B16 -> Dimensions | C12: 8x50x20 | D12: cm | E12: 6x22x11; 8x50x20; 12x55x20; 15x50x20; 20x55x20; 24x55x20; 38x55x20; 44x55x20 | F12: Technical data sheet 2017
B13: ='[1]DPP Categories'!B17 -> Height | D13: mm
B14: ='[1]DPP Categories'!B18 -> Length | D14: mm
B15: ='[1]DPP Categories'!B19 -> Width | D15: mm
B16: ='[1]DPP Categories'!B20 -> Volume | D16: —
B17: ='[1]DPP Categories'!B21 -> Dry density | C17: 335 | D17: kg/m³ | E17: 310-360 | F17: EPD 2025
B18: ='[1]DPP Categories'!B22 -> Equilibrium density | C18: 405 | D18: kg/m³ | E18: 390-450 | F18: EPD 2025
B19: ='[1]DPP Categories'!B23 -> Weight
B20: ='[1]DPP Categories'!B24 -> Compressive strength | C20: 0.5 | D20: Mpa | F20: Technical data sheet 06/2025
B21: ='[1]DPP Categories'!B25 -> Shear strength | C21: 0.12 | D21: Mpa | F21: Hempblock brochure
B22: ='[1]DPP Categories'!B31 -> Water vapour diffusion resistance when wet | C22: 3.8 | D22: μ | F22: Technical data sheet 06/2025
B23: ='[1]DPP Categories'!B32 -> Water vapour diffusion resistance when dry | C23: 4.3 | D23: μ | F23: Technical data sheet 06/2025
B24: ='[1]DPP Categories'!B33 -> Water vapour absorption resistance | C24: 19 | D24: d[g/m²vh] | F24: Technical data sheet 06/2025
B25: ='[1]DPP Categories'!B34 -> Standard compliance | C25: Yes | D25: — | E25: Yes/No | F25: German general type approval
A26: 3. Circularity and End-of-Life Information | B26: ='[1]DPP Categories'!B37 -> Prefabrication | C26: Yes | D26: — | E26: Yes/No | F26: Report for KBOB list
B27: ='[1]DPP Categories'!B38 -> Prefabrication factor | D27: Score | E27: 1 (Yes) - 0 (No) | F27: Range Atta et al. 2021
B28: ='[1]DPP Categories'!B39 -> Deconstructability score | D28: Score | E28: 0.0-1.0 | F28: Range Atta et al. 2021
B29: ='[1]DPP Categories'!B40 -> Recycling potential | D29: % | E29: 1-100% | F29: Technical data sheet 2017
B30: ='[1]DPP Categories'!B41 -> Reusability | D30: — | E30: Yes/No | F30: EPD 2025
B31: ='[1]DPP Categories'!B42 -> Reusability potential | D31: Score | E31: 0-1 | F31: Range Atta et al. 2021
B32: ='[1]DPP Categories'!B43 -> Recovery score | D32: Score | E32: 0.0-1.0 | F32: Range Atta et al. 2021
B33: ='[1]DPP Categories'!B44 -> Disassembly potential | D33: Score | E33: 1 (Dificult)- 2 (Moderate)- 3 (Easy) | F33: Range assigned
B34: ='[1]DPP Categories'!B45 -> Disassembly instructions | C34: Mechanical dismantling: Crushing and Sieving for Recycling | D34: — | F34: EPD 2025
B35: ='[1]DPP Categories'!B46 -> Secondary use scenarios | C35: Reused on the construction site for applications requiring increased density, such as floor material | D35: — | F35: EPD 2025
B36: ='[1]DPP Categories'!B47 -> End-of-life recommendation | C36: Composting and soil improvement; Disposal via incineration | D36: — | F36: EPD 2025
A37: 4. Environmental Performance and LCA Data | B37: ='[1]DPP Categories'!B48 -> EPD | C37: Yes | D37: — | E37: Yes/No | F37: By manufacturer
B38: ='[1]DPP Categories'!B49 -> Link EPD | C38: https://www.bau-epd.at/epd/data/schoenthaler-bausteinwerk-gmbh-hanfsteine-ecoinvent-2025 | D38: URL | E38: — | F38: By manufacturer
B39: ='[1]DPP Categories'!B50 -> Global Warming Potential (GWP) | D39: kg CO₂eq./ Block
B40: ='[1]DPP Categories'!B51 -> Primary Energy Intensity (PEI) Renewable | D40: MJ
...

Sheet Gap Analysis
A1: Category | B1: Parameter | C1: Available in Manufacturer Documentation | D1: Range Available? | E1: Data Source (if available) | F1: Gap Identified | G1: Proposed Supplementary Source | H1: Notes
A2: 1. Identification and General Information | B2: =+'1 Data Material DPP'!B2 -> Product Name | C2: =IF('1 Data Material DPP'!C2<>"","Yes","No") -> Yes | D2: =+IF('1 Data Material DPP'!E2="—","—",IF('1 Data Material DPP'!E2<>"","Yes","No")) -> — | E2: =+'1 Data Material DPP'!F2 -> Technical data sheet 06/2025 | F2: =IF(AND(C2="Yes",OR(D2="Yes",D2="—")),"No","Yes") -> No
B3: =+'1 Data Material DPP'!B3 -> Product ID | C3: =IF('1 Data Material DPP'!C3<>"","Yes","No") -> Yes | D3: =+IF('1 Data Material DPP'!E3="—","—",IF('1 Data Material DPP'!E3<>"","Yes","No")) -> — | E3: =+'1 Data Material DPP'!F3 -> German general type approval | F3: =IF(AND(C3="Yes",OR(D3="Yes",D3="—")),"No","Yes") -> No
B4: =+'1 Data Material DPP'!B4 -> Object number | C4: =IF('1 Data Material DPP'!C4<>"","Yes","No") -> No | D4: =+IF('1 Data Material DPP'!E4="—","—",IF('1 Data Material DPP'!E4<>"","Yes","No")) -> — | E4: =+'1 Data Material DPP'!F4 -> BIM parameter | F4: =IF(AND(C4="Yes",OR(D4="Yes",D4="—")),"No","Yes") -> Yes | G4: BIM parameter | H4: After IFC exporting
B5: =+'1 Data Material DPP'!B5 -> Material Type | C5: =IF('1 Data Material DPP'!C5<>"","Yes","No") -> No | D5: =+IF('1 Data Material DPP'!E5="—","—",IF('1 Data Material DPP'!E5<>"","Yes","No")) -> — | E5: =+'1 Data Material DPP'!F5 -> 0 | F5: =IF(AND(C5="Yes",OR(D5="Yes",D5="—")),"No","Yes") -> Yes | G5: IFC standard | H5: After IFC exporting
B6: =+'1 Data Material DPP'!B6 -> Manufacturer | C6: =IF('1 Data Material DPP'!C6<>"","Yes","No") -> Yes | D6: =+IF('1 Data Material DPP'!E6="—","—",IF('1 Data Material DPP'!E6<>"","Yes","No")) -> — | E6: =+'1 Data Material DPP'!F6 -> German general type approval | F6: =IF(AND(C6="Yes",OR(D6="Yes",D6="—")),"No","Yes") -> No
B7: =+'1 Data Material DPP'!B7 -> Traceability ID | C7: =IF('1 Data Material DPP'!C7<>"","Yes","No") -> No | D7: =+IF('1 Data Material DPP'!E7="—","—",IF('1 Data Material DPP'!E7<>"","Yes","No")) -> — | E7: =+'1 Data Material DPP'!F7 -> 0 | F7: =IF(AND(C7="Yes",OR(D7="Yes",D7="—")),"No","Yes") -> Yes | G7: BIM parameter | H7: After IFC exporting
B8: =+'1 Data Material DPP'!B8 -> Origin | C8: =IF('1 Data Material DPP'!C8<>"","Yes","No") -> Yes | D8: =+IF('1 Data Material DPP'!E8="—","—",IF('1 Data Material DPP'!E8<>"","Yes","No")) -> — | E8: =+'1 Data Material DPP'!F8 -> 0 | F8: =IF(AND(C8="Yes",OR(D8="Yes",D8="—")),"No","Yes") -> No
B9: =+'1 Data Material DPP'!B9 -> Version number | C9: =IF('1 Data Material DPP'!C9<>"","Yes","No") -> Yes | D9: =+IF('1 Data Material DPP'!E9="—","—",IF('1 Data Material DPP'!E9<>"","Yes","No")) -> Yes | E9: =+'1 Data Material DPP'!F9 -> German general type approval | F9: =IF(AND(C9="Yes",OR(D9="Yes",D9="—")),"No","Yes") -> No
A10: 2. Physical and Technical Properties | B10: =+'1 Data Material DPP'!B10 -> Material | C10: =IF('1 Data Material DPP'!C10<>"","Yes","No") -> Yes | D10: =+IF('1 Data Material DPP'!E10="—","—",IF('1 Data Material DPP'!E10<>"","Yes","No")) -> — | E10: =+'1 Data Material DPP'!F10 -> BIM parameter | F10: =IF(AND(C10="Yes",OR(D10="Yes",D10="—")),"No","Yes") -> No
B11: =+'1 Data Material DPP'!B11 -> Composition | C11: =IF('1 Data Material DPP'!C11<>"","Yes","No") -> Yes | D11: =+IF('1 Data Material DPP'!E11="—","—",IF('1 Data Material DPP'!E11<>"","Yes","No")) -> No | E11: =+'1 Data Material DPP'!F11 -> Technical data sheet 06/2025 | F11: =IF(AND(C11="Yes",OR(D11="Yes",D11="—")),"No","Yes") -> Yes | G11: Literature
B12: =+'1 Data Material DPP'!B12 -> Dimensions | C12: =IF('1 Data Material DPP'!C12<>"","Yes","No") -> Yes | D12: =+IF('1 Data Material DPP'!E12="—","—",IF('1 Data Material DPP'!E12<>"","Yes","No")) -> Yes | E12: =+'1 Data Material DPP'!F12 -> Technical data sheet 2017 | F12: =IF(AND(C12="Yes",OR(D12="Yes",D12="—")),"No","Yes") -> No
B13: =+'1 Data Material DPP'!B13 -> Height | C13: =IF('1 Data Material DPP'!C13<>"","Yes","No") -> No | D13: =+IF('1 Data Material DPP'!E13="—","—",IF('1 Data Material DPP'!E13<>"","Yes","No")) -> No | E13: =+'1 Data Material DPP'!F13 -> 0 | F13: =IF(AND(C13="Yes",OR(D13="Yes",D13="—")),"No","Yes") -> Yes | G13: BIM parameter | H13: In model
B14: =+'1 Data Material DPP'!B14 -> Length | C14: =IF('1 Data Material DPP'!C14<>"","Yes","No") -> No | D14: =+IF('1 Data Material DPP'!E14="—","—",IF('1 Data Material DPP'!E14<>"","Yes","No")) -> No | E14: =+'1 Data Material DPP'!F14 -> 0 | F14: =IF(AND(C14="Yes",OR(D14="Yes",D14="—")),"No","Yes") -> Yes | G14: BIM parameter | H14: In model
B15: =+'1 Data Material DPP'!B15 -> Width | C15: =IF('1 Data Material DPP'!C15<>"","Yes","No") -> No | D15: =+IF('1 Data Material DPP'!E15="—","—",IF('1 Data Material DPP'!E15<>"","Yes","No")) -> No | E15: =+'1 Data Material DPP'!F15 -> 0 | F15: =IF(AND(C15="Yes",OR(D15="Yes",D15="—")),"No","Yes") -> Yes | G15: BIM parameter | H15: In model
B16: =+'1 Data Material DPP'!B16 -> Volume | C16: =IF('1 Data Material DPP'!C16<>"","Yes","No") -> No | D16: =+IF('1 Data Material DPP'!E16="—","—",IF('1 Data Material DPP'!E16<>"","Yes","No")) -> No | E16: =+'1 Data Material DPP'!F16 -> 0 | F16: =IF(AND(C16="Yes",OR(D16="Yes",D16="—")),"No","Yes") -> Yes | G16: Calculate | H16: See formula file (Range by family type)
B17: =+'1 Data Material DPP'!B17 -> Dry density | C17: =IF('1 Data Material DPP'!C17<>"","Yes","No") -> Yes | D17: =+IF('1 Data Material DPP'!E17="—","—",IF('1 Data Material DPP'!E17<>"","Yes","No")) -> Yes | E17: =+'1 Data Material DPP'!F17 -> EPD 2025 | F17: =IF(AND(C17="Yes",OR(D17="Yes",D17="—")),"No","Yes") -> No
B18: =+'1 Data Material DPP'!B18 -> Equilibrium density | C18: =IF('1 Data Material DPP'!C18<>"","Yes","No") -> Yes | D18: =+IF('1 Data Material DPP'!E18="—","—",IF('1 Data Material DPP'!E18<>"","Yes","No")) -> Yes | E18: =+'1 Data Material DPP'!F18 -> EPD 2025 | F18: =IF(AND(C18="Yes",OR(D18="Yes",D18="—")),"No","Yes") -> No
B19: =+'1 Data Material DPP'!B19 -> Weight | C19: =IF('1 Data Material DPP'!C19<>"","Yes","No") -> No | D19: =+IF('1 Data Material DPP'!E19="—","—",IF('1 Data Material DPP'!E19<>"","Yes","No")) -> No | E19: =+'1 Data Material DPP'!F19 -> 0 | F19: =IF(AND(C19="Yes",OR(D19="Yes",D19="—")),"No","Yes") -> Yes | G19: Calculate | H19: See formula file (Range by family type)
B20: =+'1 Data Material DPP'!B20 -> Compressive strength | C20: =IF('1 Data Material DPP'!C20<>"","Yes","No") -> Yes | D20: =+IF('1 Data Material DPP'!E20="—","—",IF('1 Data Material DPP'!E20<>"","Yes","No")) -> No | E20: =+'1 Data Material DPP'!F20 -> Technical data sheet 06/2025 | F20: =IF(AND(C20="Yes",OR(D20="Yes",D20="—")),"No","Yes") -> Yes | G20: Literature | H20: Range by Steyn et al., 2025; Asghari & Memari, 2024
B21: =+'1 Data Material DPP'!B21 -> Shear strength | C21: =IF('1 Data Material DPP'!C21<>"","Yes","No") -> Yes | D21: =+IF('1 Data Material DPP'!E21="—","—",IF('1 Data Material DPP'!E21<>"","Yes","No")) -> No | E21: =+'1 Data Material DPP'!F21 -> Hempblock brochure | F21: =IF(AND(C21="Yes",OR(D21="Yes",D21="—")),"No","Yes") -> Yes | G21: Literature | H21: Range by Steyn et al., 2025; Brzyski et al., 2020
B22: =+'1 Data Material DPP'!B22 -> Water vapour diffusion resistance when wet | C22: =IF('1 Data Material DPP'!C22<>"","Yes","No") -> Yes | D22: =+IF('1 Data Material DPP'!E22="—","—",IF('1 Data Material DPP'!E22<>"","Yes","No")) -> No | E22: =+'1 Data Material DPP'!F22 -> Technical data sheet 06/2025 | F22: =IF(AND(C22="Yes",OR(D22="Yes",D22="—")),"No","Yes") -> Yes | G22: Literature
B23: =+'1 Data Material DPP'!B23 -> Water vapour diffusion resistance when dry | C23: =IF('1 Data Material DPP'!C23<>"","Yes","No") -> Yes | D23: =+IF('1 Data Material DPP'!E23="—","—",IF('1 Data Material DPP'!E23<>"","Yes","No")) -> No | E23: =+'1 Data Material DPP'!F23 -> Technical data sheet 06/2025 | F23: =IF(AND(C23="Yes",OR(D23="Yes",D23="—")),"No","Yes") -> Yes | G23: Literature
B24: =+'1 Data Material DPP'!B24 -> Water vapour absorption resistance | C24: =IF('1 Data Material DPP'!C24<>"","Yes","No") -> Yes | D24: =+IF('1 Data Material DPP'!E24="—","—",IF('1 Data Material DPP'!E24<>"","Yes","No")) -> No | E24: =+'1 Data Material DPP'!F24 -> Technical data sheet 06/2025 | F24: =IF(AND(C24="Yes",OR(D24="Yes",D24="—")),"No","Yes") -> Yes | G24: Literature
B25: =+'1 Data Material DPP'!B25 -> Standard compliance | C25: =IF('1 Data Material DPP'!C25<>"","Yes","No") -> Yes | D25: =+IF('1 Data Material DPP'!E25="—","—",IF('1 Data Material DPP'!E25<>"","Yes","No")) -> Yes | E25: =+'1 Data Material DPP'!F25 -> German general type approval | F25: =IF(AND(C25="Yes",OR(D25="Yes",D25="—")),"No","Yes") -> No
A26: 3. Circularity and End-of-Life Information | B26: =+'1 Data Material DPP'!B26 -> Prefabrication | C26: =IF('1 Data Material DPP'!C26<>"","Yes","No") -> Yes | D26: =+IF('1 Data Material DPP'!E26="—","—",IF('1 Data Material DPP'!E26<>"","Yes","No")) -> Yes | E26: =+'1 Data Material DPP'!F26 -> Report for KBOB list | F26: =IF(AND(C26="Yes",OR(D26="Yes",D26="—")),"No","Yes") -> No
B27: =+'1 Data Material DPP'!B27 -> Prefabrication factor | C27: =IF('1 Data Material DPP'!C27<>"","Yes","No") -> No | D27: =+IF('1 Data Material DPP'!E27="—","—",IF('1 Data Material DPP'!E27<>"","Yes","No")) -> Yes | E27: =+'1 Data Material DPP'!F27 -> Range Atta et al. 2021 | F27: =IF(AND(C27="Yes",OR(D27="Yes",D27="—")),"No","Yes") -> Yes | G27: Assign | H27: If statement - see formula file (Rp)
B28: =+'1 Data Material DPP'!B28 -> Deconstructability score | C28: =IF('1 Data Material DPP'!C28<>"","Yes","No") -> No | D28: =+IF('1 Data Material DPP'!E28="—","—",IF('1 Data Material DPP'!E28<>"","Yes","No")) -> Yes | E28: =+'1 Data Material DPP'!F28 -> Range Atta et al. 2021 | F28: =IF(AND(C28="Yes",OR(D28="Yes",D28="—")),"No","Yes") -> Yes | G28: Calculate | H28: D=(Dc+Rp)/2 (See formula file)
B29: =+'1 Data Material DPP'!B29 -> Recycling potential | C29: =IF('1 Data Material DPP'!C29<>"","Yes","No") -> No | D29: =+IF('1 Data Material DPP'!E29="—","—",IF('1 Data Material DPP'!E29<>"","Yes","No")) -> Yes | E29: =+'1 Data Material DPP'!F29 -> Technical data sheet 2017 | F29: =IF(AND(C29="Yes",OR(D29="Yes",D29="—")),"No","Yes") -> Yes | H29: (Rc)=%/100
B30: =+'1 Data Material DPP'!B30 -> Reusability | C30: =IF('1 Data Material DPP'!C30<>"","Yes","No") -> No | D30: =+IF('1 Data Material DPP'!E30="—","—",IF('1 Data Material DPP'!E30<>"","Yes","No")) -> Yes | E30: =+'1 Data Material DPP'!F30 -> EPD 2025 | F30: =IF(AND(C30="Yes",OR(D30="Yes",D30="—")),"No","Yes") -> Yes
B31: =+'1 Data Material DPP'!B31 -> Reusability potential | C31: =IF('1 Data Material DPP'!C31<>"","Yes","No") -> No | D31: =+IF('1 Data Material DPP'!E31="—","—",IF('1 Data Material DPP'!E31<>"","Yes","No")) -> Yes | E31: =+'1 Data Material DPP'!F31 -> Range Atta et al. 2021 | F31: =IF(AND(C31="Yes",OR(D31="Yes",D31="—")),"No","Yes") -> Yes | G31: Assign | H31: If statement - see formula file (Ru)
B32: =+'1 Data Material DPP'!B32 -> Recovery score | C32: =IF('1 Data Material DPP'!C32<>"","Yes","No") -> No | D32: =+IF('1 Data Material DPP'!E32="—","—",IF('1 Data Material DPP'!E32<>"","Yes","No")) -> Yes | E32: =+'1 Data Material DPP'!F32 -> Range Atta et al. 2021 | F32: =IF(AND(C32="Yes",OR(D32="Yes",D32="—")),"No","Yes") -> Yes | G32: Calculate | H32: R=(Ru+Rc+Nx+Nc)/4
B33: =+'1 Data Material DPP'!B33 -> Disassembly potential | C33: =IF('1 Data Material DPP'!C33<>"","Yes","No") -> No | D33: =+IF('1 Data Material DPP'!E33="—","—",IF('1 Data Material DPP'!E33<>"","Yes","No")) -> Yes | E33: =+'1 Data Material DPP'!F33 -> Range assigned | F33: =IF(AND(C33="Yes",OR(D33="Yes",D33="—")),"No","Yes") -> Yes | G33: Assign | H33: Based on Range
B34: =+'1 Data Material DPP'!B34 -> Disassembly instructions | C34: =IF('1 Data Material DPP'!C34<>"","Yes","No") -> Yes | D34: =+IF('1 Data Material DPP'!E34="—","—",IF('1 Data Material DPP'!E34<>"","Yes","No")) -> No | E34: =+'1 Data Material DPP'!F34 -> EPD 2025 | F34: =IF(AND(C34="Yes",OR(D34="Yes",D34="—")),"No","Yes") -> Yes | G34: Literature
B35: =+'1 Data Material DPP'!B35 -> Secondary use scenarios | C35: =IF('1 Data Material DPP'!C35<>"","Yes","No") -> Yes | D35: =+IF('1 Data Material DPP'!E35="—","—",IF('1 Data Material DPP'!E35<>"","Yes","No")) -> No | E35: =+'1 Data Material DPP'!F35 -> EPD 2025 | F35: =IF(AND(C35="Yes",OR(D35="Yes",D35="—")),"No","Yes") -> Yes | G35: Literature
B36: =+'1 Data Material DPP'!B36 -> End-of-life recommendation | C36: =IF('1 Data Material DPP'!C36<>"","Yes","No") -> Yes | D36: =+IF('1 Data Material DPP'!E36="—","—",IF('1 Data Material DPP'!E36<>"","Yes","No")) -> No | E36: =+'1 Data Material DPP'!F36 -> EPD 2025 | F36: =IF(AND(C36="Yes",OR(D36="Yes",D36="—")),"No","Yes") -> Yes | G36: Literature
A37: 4. Environmental Performance and LCA Data | B37: =+'1 Data Material DPP'!B37 -> EPD | C37: =IF('1 Data Material DPP'!C37<>"","Yes","No") -> Yes | D37: =+IF('1 Data Material DPP'!E37="—","—",IF('1 Data Material DPP'!E37<>"","Yes","No")) -> Yes | E37: =+'1 Data Material DPP'!F37 -> By manufacturer | F37: =IF(AND(C37="Yes",OR(D37="Yes",D37="—")),"No","Yes") -> No
B38: =+'1 Data Material DPP'!B38 -> Link EPD | C38: =IF('1 Data Material DPP'!C38<>"","Yes","No") -> Yes | D38: =+IF('1 Data Material DPP'!E38="—","—",IF('1 Data Material DPP'!E38<>"","Yes","No")) -> — | E38: =+'1 Data Material DPP'!F38 -> By manufacturer | F38: =IF(AND(C38="Yes",OR(D38="Yes",D38="—")),"No","Yes") -> No
B39: =+'1 Data Material DPP'!B39 -> Global Warming Potential (GWP) | C39: =IF('1 Data Material DPP'!C39<>"","Yes","No") -> No | D39: =+IF('1 Data Material DPP'!E39="—","—",IF('1 Data Material DPP'!E39<>"","Yes","No")) -> No | E39: =+'1 Data Material DPP'!F39 -> 0 | F39: =IF(AND(C39="Yes",OR(D39="Yes",D39="—")),"No","Yes") -> Yes | G39: Calculate | H39: Sum of total GWP of avalable stages / funtional unit (See formula file)
B40: =+'1 Data Material DPP'!B40 -> Primary Energy Intensity (PEI) Renewable | C40: =IF('1 Data Material DPP'!C40<>"","Yes","No") -> No | D40: =+IF('1 Data Material DPP'!E40="—","—",IF('1 Data Material DPP'!E40<>"","Yes","No")) -> No | E40: =+'1 Data Material DPP'!F40 -> 0 | F40: =IF(AND(C40="Yes",OR(D40="Yes",D40="—")),"No","Yes") -> Yes | G40: Calculate | H40: Sum of PERT of avalable stages / funtional unit (See formula file)
...

Sheet 2 Data DPP Material
A1: Category | B1: Parameter | C1: Data | D1: Unit | E1: Range | F1: Source | G1: Filled?
A2: 1. Identification and General Information | B2: ='[1]DPP Categories'!B2 -> Product Name | C2: Hempstone | D2: — | E2: — | F2: Technical data sheet 06/2025 | G2: =IF(AND(C2<>"",E2<>""),"Yes","No") -> Yes
B3: ='[1]DPP Categories'!B3 -> Product ID | C3: Z-17.25-1299 | D3: ID | E3: — | F3: German general type approval | G3: =IF(AND(C3<>"",E3<>""),"Yes","No") -> Yes
B4: ='[1]DPP Categories'!B4 -> Object number | D4: GUID | E4: — | F4: BIM parameter | G4: =IF(AND(C4<>"",E4<>""),"Yes","No") -> No
B5: ='[1]DPP Categories'!B5 -> Material Type | C5: Type II | D5: — | E5: Type I (Ingredients); Type II (Modular); Type III (Sub-Components) | F5: Waterman materials passport framework 2023 | G5: =IF(AND(C5<>"",E5<>""),"Yes","No") -> Yes
B6: ='[1]DPP Categories'!B6 -> Manufacturer | C6: Schönthaler Bausteinwerk GmbH | D6: — | E6: — | F6: German general type approval | G6: =IF(AND(C6<>"",E6<>""),"Yes","No") -> Yes
B7: ='[1]DPP Categories'!B10 -> Traceability ID | E7: — | G7: =IF(AND(C7<>"",E7<>""),"Yes","No") -> No
B8: ='[1]DPP Categories'!B11 -> Origin | C8: 39020 Oris (BZ) | D8: — | E8: — | F8: German general type approval | G8: =IF(AND(C8<>"",E8<>""),"Yes","No") -> Yes
B9: ='[1]DPP Categories'!B12 -> Version number | C9: HKZ 335 | D9: No. | E9: HKZ 335 - HKZ 360 | F9: Assigned | G9: =IF(AND(C9<>"",E9<>""),"Yes","No") -> Yes
A10: 2. Physical and Technical Properties | B10: ='[1]DPP Categories'!B13 -> Material | C10: Infill masonry made of hemp stones | D10: — | E10: — | F10: BIM parameter | G10: =IF(AND(C10<>"",E10<>""),"Yes","No") -> Yes
B11: ='[1]DPP Categories'!B15 -> Composition | C11: Hemp-lime composite | D11: — | E11: Hemp-clay; Hemp-cement; Hemp-biopolymer; Hemp-MgO | F11: Technical data sheet 06/2025 (Range by Steyn et al., 2025; Barbhuiya & Bhusan, 2022) | G11: =IF(AND(C11<>"",E12<>""),"Yes","No") -> Yes
B12: ='[1]DPP Categories'!B16 -> Dimensions | C12: 8x50x20 | D12: cm | E12: 6x22x11; 8x50x20; 12x55x20; 15x50x20; 20x55x20; 24x55x20; 38x55x20; 44x55x20 | F12: Technical data sheet 2017 | G12: =IF(AND(C12<>"",E12<>""),"Yes","No") -> Yes
B13: ='[1]DPP Categories'!B17 -> Height | C13: 200 | D13: mm | E13: 200 - 300 | F13: BIM parameter (Range by standard masonry formats) | G13: =IF(AND(C13<>"",E13<>""),"Yes","No") -> Yes
B14: ='[1]DPP Categories'!B18 -> Length | C14: 80 | D14: mm | E14: 100 - 250 | F14: BIM parameter (Range by standard masonry formats) | G14: =IF(AND(C14<>"",E14<>""),"Yes","No") -> Yes
B15: ='[1]DPP Categories'!B19 -> Width | C15: 500 | D15: mm | E15: 300 - 600 | F15: BIM parameter (Range by standard masonry formats) | G15: =IF(AND(C15<>"",E15<>""),"Yes","No") -> Yes
B16: ='[1]DPP Categories'!B20 -> Volume | C16: =+(C13/1000)*(C14/1000)*(C15/1000) -> 0.008 | D16: — | E16: 0.006 - 0.036 | F16: Calculated | G16: =IF(AND(C16<>"",E16<>""),"Yes","No") -> Yes
B17: ='[1]DPP Categories'!B21 -> Dry density | C17: 335 | D17: kg/m³ | E17: 310-360 | F17: EPD 2025 | G17: =IF(AND(C17<>"",E17<>""),"Yes","No") -> Yes
B18: ='[1]DPP Categories'!B22 -> Equilibrium density | C18: 405 | D18: kg/m³ | E18: 390-450 | F18: EPD 2025 | G18: =IF(AND(C18<>"",E18<>""),"Yes","No") -> Yes
B19: ='[1]DPP Categories'!B23 -> Weight | C19: =+C17*C16 -> 2.68 | D19: Kg | E19: 6.00 - 15.00 | F19: Calculated | G19: =IF(AND(C19<>"",E19<>""),"Yes","No") -> Yes
B20: ='[1]DPP Categories'!B24 -> Compressive strength | C20: 0.5 | D20: Mpa | E20: 0.06-0.8 | F20: Technical data sheet 06/2025 (Range by Steyn et al., 2025; Asghari & Memari, 2024) | G20: =IF(AND(C20<>"",E20<>""),"Yes","No") -> Yes
B21: ='[1]DPP Categories'!B25 -> Shear strength | C21: 0.12 | D21: Mpa | E21: 0.08-0.15 | F21: Hempblock brochure (Range by Steyn et al., 2025; Brzyski et al., 2020) | G21: =IF(AND(C21<>"",E21<>""),"Yes","No") -> Yes
B22: ='[1]DPP Categories'!B31 -> Water vapour diffusion resistance when wet | C22: 3.8 | D22: μ | E22: 4.9 - 5.7 | F22: Technical data sheet 06/2025 (Range by Brzyski et al., 2020) | G22: =IF(AND(C22<>"",E22<>""),"Yes","No") -> Yes
B23: ='[1]DPP Categories'!B32 -> Water vapour diffusion resistance when dry | C23: 4.3 | D23: μ | E23: 12.2 - 12.4 | F23: Technical data sheet 06/2025 (Range by Brzyski et al., 2020) | G23: =IF(AND(C23<>"",E23<>""),"Yes","No") -> Yes
B24: ='[1]DPP Categories'!B33 -> Water vapour absorption resistance | C24: 19 | D24: d[g/m²vh] | E24: — | F24: Technical data sheet 06/2025 | G24: =IF(AND(C24<>"",E24<>""),"Yes","No") -> Yes
B25: ='[1]DPP Categories'!B34 -> Standard compliance | C25: Yes | D25: — | E25: Yes/No | F25: German general type approval | G25: =IF(AND(C25<>"",E25<>""),"Yes","No") -> Yes
A26: 3. Circularity and End-of-Life Information | B26: ='[1]DPP Categories'!B37 -> Prefabrication | C26: Yes | D26: — | E26: Yes/No | F26: Report for KBOB list | G26: =IF(AND(C26<>"",E26<>""),"Yes","No") -> Yes
B27: ='[1]DPP Categories'!B38 -> Prefabrication factor | C27: =+IF(C26="Yes",1,0) -> 1 | D27: Score | E27: 1 (Yes) - 0 (No) | F27: Range Atta et al. 2021 | G27: =IF(AND(C27<>"",E27<>""),"Yes","No") -> Yes
B28: ='[1]DPP Categories'!B39 -> Deconstructability score | C28: =+(0+C27)/2 -> 0.5 | D28: Score | E28: 0.0-1.0 | F28: Range Atta et al. 2021 | G28: =IF(AND(C28<>"",E28<>""),"Yes","No") -> Yes
B29: ='[1]DPP Categories'!B40 -> Recycling potential | C29: 100 | D29: % | E29: 1-100% | F29: Technical data sheet 2017 | G29: =IF(AND(C29<>"",E29<>""),"Yes","No") -> Yes
B30: ='[1]DPP Categories'!B41 -> Reusability | C30: No | D30: — | E30: Yes/No | F30: EPD 2025 | G30: =IF(AND(C30<>"",E30<>""),"Yes","No") -> Yes
B31: ='[1]DPP Categories'!B42 -> Reusability potential | C31: =+IF(C30="Yes",1,0) -> 0 | D31: Score | E31: 0-1 | F31: Range Atta et al. 2021 | G31: =IF(AND(C31<>"",E31<>""),"Yes","No") -> Yes
B32: ='[1]DPP Categories'!B43 -> Recovery score | C32: =+((C29/100)+C31+(IF(C63="No",1,0))+(IF(C69="No",1,0)))/4 -> 0.5 | D32: Score | E32: 0.0-1.0 | F32: Range Atta et al. 2021 | G32: =IF(AND(C32<>"",E32<>""),"Yes","No") -> Yes
B33: ='[1]DPP Categories'!B44 -> Disassembly potential | C33: 3 | D33: Score | E33: 1 (Dificult)- 2 (Moderate)- 3 (Easy) | F33: Range assigned | G33: =IF(AND(C33<>"",E33<>""),"Yes","No") -> Yes
B34: ='[1]DPP Categories'!B45 -> Disassembly instructions | C34: Mechanical dismantling: Crushing and Sieving for Recycling | D34: — | E34: Manual dismantling; Semi-Mechanical Disassembly; Thermal Disassembly; Chemical Disassembly; Demolition; Modular Disassembly | F34: EPD 2025 (Range by ISO 20887:2020) | G34: =IF(AND(C34<>"",E34<>""),"Yes","No") -> Yes
B35: ='[1]DPP Categories'!B46 -> Secondary use scenarios | C35: Reused on the construction site for applications requiring increased density, such as floor material | D35: — | E35: Direc reuse; Partial reuse; Reprocessing into aggregare; Soil amendment; Upcycling into thermal or acoustic insulation; Upcycling into new composites or panels; Backfilling | F35: EPD 2025 (Range by European Commission 2020, LEVEL(s)) | G35: =IF(AND(C35<>"",E35<>""),"Yes","No") -> Yes
B36: ='[1]DPP Categories'!B47 -> End-of-life recommendation | C36: Composting and soil improvement; Disposal via incineration | D36: — | E36: Biological recovery; Material recyclcing; Energy recovery; Landfill disposal | F36: EPD 2025 (Range by EN 15804:2012 +A2:2019) | G36: =IF(AND(C36<>"",E36<>""),"Yes","No") -> Yes
A37: 4. Environmental Performance and LCA Data | B37: ='[1]DPP Categories'!B48 -> EPD | C37: Yes | D37: — | E37: Yes/No | F37: By manufacturer | G37: =IF(AND(C37<>"",E37<>""),"Yes","No") -> Yes
B38: ='[1]DPP Categories'!B49 -> Link EPD | C38: https://www.bau-epd.at/epd/data/schoenthaler-bausteinwerk-gmbh-hanfsteine-ecoinvent-2025 | D38: URL | E38: — | F38: By manufacturer | G38: =IF(AND(C38<>"",E38<>""),"Yes","No") -> Yes
B39: ='[1]DPP Categories'!B50 -> Global Warming Potential (GWP) | C39: =167.4*C16 -> 1.3392 | D39: kg CO₂eq./ Block | E39: -6.6 - 3.8 | F39: Calculated from EPD (Range derived from published volumetric ranges (≈ −184 to +105 kg CO₂e/m³)) | G39: =IF(AND(C39<>"",E39<>""),"Yes","No") -> Yes
B40: ='[1]DPP Categories'!B51 -> Primary Energy Intensity (PEI) Renewable | C40: =2301.09*C16 -> 18.40872 | D40: MJ | E40: 10 - 30 | F40: Calculated from EPD (Range corresponds to ≈ 2.5 – 3.5 MJ/kg embodied energy for densities of 300–330 kg/m3) | G40: =IF(AND(C40<>"",E40<>""),"Yes","No") -> Yes
...
